2025-09-14 12:47:43,870 ERROR scheduler Exception in Enqueue Events for Site test-site.local
Traceback (most recent call last):
  File "/home/ubuntu/test-hrms/env/lib/python3.11/site-packages/redis/connection.py", line 699, in connect
    sock = self.retry.call_with_retry(
           ^^^^^^^^^^^^^^^^^^^^^^^^^^^
  File "/home/ubuntu/test-hrms/env/lib/python3.11/site-packages/redis/retry.py", line 46, in call_with_retry
    return do()
           ^^^^
  File "/home/ubuntu/test-hrms/env/lib/python3.11/site-packages/redis/connection.py", line 700, in <lambda>
    lambda: self._connect(), lambda error: self.disconnect(error)
            ^^^^^^^^^^^^^^^
  File "/home/ubuntu/test-hrms/env/lib/python3.11/site-packages/redis/connection.py", line 1002, in _connect
    raise err
  File "/home/ubuntu/test-hrms/env/lib/python3.11/site-packages/redis/connection.py", line 990, in _connect
    sock.connect(socket_address)
ConnectionRefusedError: [Errno 111] Connection refused

During handling of the above exception, another exception occurred:

Traceback (most recent call last):
  File "/home/ubuntu/test-hrms/apps/frappe/frappe/utils/scheduler.py", line 102, in enqueue_events_for_site
    enqueue_events(site=site)
  File "/home/ubuntu/test-hrms/apps/frappe/frappe/utils/scheduler.py", line 122, in enqueue_events
    if job_type.enqueue():
       ^^^^^^^^^^^^^^^^^^
  File "/home/ubuntu/test-hrms/apps/frappe/frappe/core/doctype/scheduled_job_type/scheduled_job_type.py", line 74, in enqueue
    if not self.is_job_in_queue():
           ^^^^^^^^^^^^^^^^^^^^^^
  File "/home/ubuntu/test-hrms/apps/frappe/frappe/core/doctype/scheduled_job_type/scheduled_job_type.py", line 95, in is_job_in_queue
    return is_job_enqueued(self.rq_job_id)
           ^^^^^^^^^^^^^^^^^^^^^^^^^^^^^^^
  File "/home/ubuntu/test-hrms/apps/frappe/frappe/utils/background_jobs.py", line 568, in is_job_enqueued
    return get_job_status(job_id) in (JobStatus.QUEUED, JobStatus.STARTED)
           ^^^^^^^^^^^^^^^^^^^^^^
  File "/home/ubuntu/test-hrms/apps/frappe/frappe/utils/background_jobs.py", line 573, in get_job_status
    job = get_job(job_id)
          ^^^^^^^^^^^^^^^
  File "/home/ubuntu/test-hrms/apps/frappe/frappe/utils/background_jobs.py", line 580, in get_job
    return Job.fetch(create_job_id(job_id), connection=get_redis_conn())
           ^^^^^^^^^^^^^^^^^^^^^^^^^^^^^^^^^^^^^^^^^^^^^^^^^^^^^^^^^^^^^
  File "/home/ubuntu/test-hrms/env/lib/python3.11/site-packages/rq/job.py", line 591, in fetch
    job.refresh()
  File "/home/ubuntu/test-hrms/env/lib/python3.11/site-packages/rq/job.py", line 989, in refresh
    data = self.connection.hgetall(self.key)
           ^^^^^^^^^^^^^^^^^^^^^^^^^^^^^^^^^
  File "/home/ubuntu/test-hrms/env/lib/python3.11/site-packages/redis/commands/core.py", line 4887, in hgetall
    return self.execute_command("HGETALL", name)
           ^^^^^^^^^^^^^^^^^^^^^^^^^^^^^^^^^^^^^
  File "/home/ubuntu/test-hrms/env/lib/python3.11/site-packages/redis/client.py", line 1266, in execute_command
    conn = self.connection or pool.get_connection(command_name, **options)
                              ^^^^^^^^^^^^^^^^^^^^^^^^^^^^^^^^^^^^^^^^^^^^
  File "/home/ubuntu/test-hrms/env/lib/python3.11/site-packages/redis/connection.py", line 1457, in get_connection
    connection.connect()
  File "/home/ubuntu/test-hrms/env/lib/python3.11/site-packages/redis/connection.py", line 705, in connect
    raise ConnectionError(self._error_message(e))
redis.exceptions.ConnectionError: Error 111 connecting to 127.0.0.1:11000. Connection refused.
2025-09-14 12:48:43,959 ERROR scheduler Exception in Enqueue Events for Site test-site.local
Traceback (most recent call last):
  File "/home/ubuntu/test-hrms/env/lib/python3.11/site-packages/redis/connection.py", line 699, in connect
    sock = self.retry.call_with_retry(
           ^^^^^^^^^^^^^^^^^^^^^^^^^^^
  File "/home/ubuntu/test-hrms/env/lib/python3.11/site-packages/redis/retry.py", line 46, in call_with_retry
    return do()
           ^^^^
  File "/home/ubuntu/test-hrms/env/lib/python3.11/site-packages/redis/connection.py", line 700, in <lambda>
    lambda: self._connect(), lambda error: self.disconnect(error)
            ^^^^^^^^^^^^^^^
  File "/home/ubuntu/test-hrms/env/lib/python3.11/site-packages/redis/connection.py", line 1002, in _connect
    raise err
  File "/home/ubuntu/test-hrms/env/lib/python3.11/site-packages/redis/connection.py", line 990, in _connect
    sock.connect(socket_address)
ConnectionRefusedError: [Errno 111] Connection refused

During handling of the above exception, another exception occurred:

Traceback (most recent call last):
  File "/home/ubuntu/test-hrms/apps/frappe/frappe/utils/scheduler.py", line 102, in enqueue_events_for_site
    enqueue_events(site=site)
  File "/home/ubuntu/test-hrms/apps/frappe/frappe/utils/scheduler.py", line 122, in enqueue_events
    if job_type.enqueue():
       ^^^^^^^^^^^^^^^^^^
  File "/home/ubuntu/test-hrms/apps/frappe/frappe/core/doctype/scheduled_job_type/scheduled_job_type.py", line 74, in enqueue
    if not self.is_job_in_queue():
           ^^^^^^^^^^^^^^^^^^^^^^
  File "/home/ubuntu/test-hrms/apps/frappe/frappe/core/doctype/scheduled_job_type/scheduled_job_type.py", line 95, in is_job_in_queue
    return is_job_enqueued(self.rq_job_id)
           ^^^^^^^^^^^^^^^^^^^^^^^^^^^^^^^
  File "/home/ubuntu/test-hrms/apps/frappe/frappe/utils/background_jobs.py", line 568, in is_job_enqueued
    return get_job_status(job_id) in (JobStatus.QUEUED, JobStatus.STARTED)
           ^^^^^^^^^^^^^^^^^^^^^^
  File "/home/ubuntu/test-hrms/apps/frappe/frappe/utils/background_jobs.py", line 573, in get_job_status
    job = get_job(job_id)
          ^^^^^^^^^^^^^^^
  File "/home/ubuntu/test-hrms/apps/frappe/frappe/utils/background_jobs.py", line 580, in get_job
    return Job.fetch(create_job_id(job_id), connection=get_redis_conn())
           ^^^^^^^^^^^^^^^^^^^^^^^^^^^^^^^^^^^^^^^^^^^^^^^^^^^^^^^^^^^^^
  File "/home/ubuntu/test-hrms/env/lib/python3.11/site-packages/rq/job.py", line 591, in fetch
    job.refresh()
  File "/home/ubuntu/test-hrms/env/lib/python3.11/site-packages/rq/job.py", line 989, in refresh
    data = self.connection.hgetall(self.key)
           ^^^^^^^^^^^^^^^^^^^^^^^^^^^^^^^^^
  File "/home/ubuntu/test-hrms/env/lib/python3.11/site-packages/redis/commands/core.py", line 4887, in hgetall
    return self.execute_command("HGETALL", name)
           ^^^^^^^^^^^^^^^^^^^^^^^^^^^^^^^^^^^^^
  File "/home/ubuntu/test-hrms/env/lib/python3.11/site-packages/redis/client.py", line 1266, in execute_command
    conn = self.connection or pool.get_connection(command_name, **options)
                              ^^^^^^^^^^^^^^^^^^^^^^^^^^^^^^^^^^^^^^^^^^^^
  File "/home/ubuntu/test-hrms/env/lib/python3.11/site-packages/redis/connection.py", line 1457, in get_connection
    connection.connect()
  File "/home/ubuntu/test-hrms/env/lib/python3.11/site-packages/redis/connection.py", line 705, in connect
    raise ConnectionError(self._error_message(e))
redis.exceptions.ConnectionError: Error 111 connecting to 127.0.0.1:11000. Connection refused.
2025-09-14 12:49:44,040 ERROR scheduler Exception in Enqueue Events for Site test-site.local
Traceback (most recent call last):
  File "/home/ubuntu/test-hrms/env/lib/python3.11/site-packages/redis/connection.py", line 699, in connect
    sock = self.retry.call_with_retry(
           ^^^^^^^^^^^^^^^^^^^^^^^^^^^
  File "/home/ubuntu/test-hrms/env/lib/python3.11/site-packages/redis/retry.py", line 46, in call_with_retry
    return do()
           ^^^^
  File "/home/ubuntu/test-hrms/env/lib/python3.11/site-packages/redis/connection.py", line 700, in <lambda>
    lambda: self._connect(), lambda error: self.disconnect(error)
            ^^^^^^^^^^^^^^^
  File "/home/ubuntu/test-hrms/env/lib/python3.11/site-packages/redis/connection.py", line 1002, in _connect
    raise err
  File "/home/ubuntu/test-hrms/env/lib/python3.11/site-packages/redis/connection.py", line 990, in _connect
    sock.connect(socket_address)
ConnectionRefusedError: [Errno 111] Connection refused

During handling of the above exception, another exception occurred:

Traceback (most recent call last):
  File "/home/ubuntu/test-hrms/apps/frappe/frappe/utils/scheduler.py", line 102, in enqueue_events_for_site
    enqueue_events(site=site)
  File "/home/ubuntu/test-hrms/apps/frappe/frappe/utils/scheduler.py", line 122, in enqueue_events
    if job_type.enqueue():
       ^^^^^^^^^^^^^^^^^^
  File "/home/ubuntu/test-hrms/apps/frappe/frappe/core/doctype/scheduled_job_type/scheduled_job_type.py", line 74, in enqueue
    if not self.is_job_in_queue():
           ^^^^^^^^^^^^^^^^^^^^^^
  File "/home/ubuntu/test-hrms/apps/frappe/frappe/core/doctype/scheduled_job_type/scheduled_job_type.py", line 95, in is_job_in_queue
    return is_job_enqueued(self.rq_job_id)
           ^^^^^^^^^^^^^^^^^^^^^^^^^^^^^^^
  File "/home/ubuntu/test-hrms/apps/frappe/frappe/utils/background_jobs.py", line 568, in is_job_enqueued
    return get_job_status(job_id) in (JobStatus.QUEUED, JobStatus.STARTED)
           ^^^^^^^^^^^^^^^^^^^^^^
  File "/home/ubuntu/test-hrms/apps/frappe/frappe/utils/background_jobs.py", line 573, in get_job_status
    job = get_job(job_id)
          ^^^^^^^^^^^^^^^
  File "/home/ubuntu/test-hrms/apps/frappe/frappe/utils/background_jobs.py", line 580, in get_job
    return Job.fetch(create_job_id(job_id), connection=get_redis_conn())
           ^^^^^^^^^^^^^^^^^^^^^^^^^^^^^^^^^^^^^^^^^^^^^^^^^^^^^^^^^^^^^
  File "/home/ubuntu/test-hrms/env/lib/python3.11/site-packages/rq/job.py", line 591, in fetch
    job.refresh()
  File "/home/ubuntu/test-hrms/env/lib/python3.11/site-packages/rq/job.py", line 989, in refresh
    data = self.connection.hgetall(self.key)
           ^^^^^^^^^^^^^^^^^^^^^^^^^^^^^^^^^
  File "/home/ubuntu/test-hrms/env/lib/python3.11/site-packages/redis/commands/core.py", line 4887, in hgetall
    return self.execute_command("HGETALL", name)
           ^^^^^^^^^^^^^^^^^^^^^^^^^^^^^^^^^^^^^
  File "/home/ubuntu/test-hrms/env/lib/python3.11/site-packages/redis/client.py", line 1266, in execute_command
    conn = self.connection or pool.get_connection(command_name, **options)
                              ^^^^^^^^^^^^^^^^^^^^^^^^^^^^^^^^^^^^^^^^^^^^
  File "/home/ubuntu/test-hrms/env/lib/python3.11/site-packages/redis/connection.py", line 1457, in get_connection
    connection.connect()
  File "/home/ubuntu/test-hrms/env/lib/python3.11/site-packages/redis/connection.py", line 705, in connect
    raise ConnectionError(self._error_message(e))
redis.exceptions.ConnectionError: Error 111 connecting to 127.0.0.1:11000. Connection refused.
2025-09-14 12:50:44,128 ERROR scheduler Exception in Enqueue Events for Site test-site.local
Traceback (most recent call last):
  File "/home/ubuntu/test-hrms/env/lib/python3.11/site-packages/redis/connection.py", line 699, in connect
    sock = self.retry.call_with_retry(
           ^^^^^^^^^^^^^^^^^^^^^^^^^^^
  File "/home/ubuntu/test-hrms/env/lib/python3.11/site-packages/redis/retry.py", line 46, in call_with_retry
    return do()
           ^^^^
  File "/home/ubuntu/test-hrms/env/lib/python3.11/site-packages/redis/connection.py", line 700, in <lambda>
    lambda: self._connect(), lambda error: self.disconnect(error)
            ^^^^^^^^^^^^^^^
  File "/home/ubuntu/test-hrms/env/lib/python3.11/site-packages/redis/connection.py", line 1002, in _connect
    raise err
  File "/home/ubuntu/test-hrms/env/lib/python3.11/site-packages/redis/connection.py", line 990, in _connect
    sock.connect(socket_address)
ConnectionRefusedError: [Errno 111] Connection refused

During handling of the above exception, another exception occurred:

Traceback (most recent call last):
  File "/home/ubuntu/test-hrms/apps/frappe/frappe/utils/scheduler.py", line 102, in enqueue_events_for_site
    enqueue_events(site=site)
  File "/home/ubuntu/test-hrms/apps/frappe/frappe/utils/scheduler.py", line 122, in enqueue_events
    if job_type.enqueue():
       ^^^^^^^^^^^^^^^^^^
  File "/home/ubuntu/test-hrms/apps/frappe/frappe/core/doctype/scheduled_job_type/scheduled_job_type.py", line 74, in enqueue
    if not self.is_job_in_queue():
           ^^^^^^^^^^^^^^^^^^^^^^
  File "/home/ubuntu/test-hrms/apps/frappe/frappe/core/doctype/scheduled_job_type/scheduled_job_type.py", line 95, in is_job_in_queue
    return is_job_enqueued(self.rq_job_id)
           ^^^^^^^^^^^^^^^^^^^^^^^^^^^^^^^
  File "/home/ubuntu/test-hrms/apps/frappe/frappe/utils/background_jobs.py", line 568, in is_job_enqueued
    return get_job_status(job_id) in (JobStatus.QUEUED, JobStatus.STARTED)
           ^^^^^^^^^^^^^^^^^^^^^^
  File "/home/ubuntu/test-hrms/apps/frappe/frappe/utils/background_jobs.py", line 573, in get_job_status
    job = get_job(job_id)
          ^^^^^^^^^^^^^^^
  File "/home/ubuntu/test-hrms/apps/frappe/frappe/utils/background_jobs.py", line 580, in get_job
    return Job.fetch(create_job_id(job_id), connection=get_redis_conn())
           ^^^^^^^^^^^^^^^^^^^^^^^^^^^^^^^^^^^^^^^^^^^^^^^^^^^^^^^^^^^^^
  File "/home/ubuntu/test-hrms/env/lib/python3.11/site-packages/rq/job.py", line 591, in fetch
    job.refresh()
  File "/home/ubuntu/test-hrms/env/lib/python3.11/site-packages/rq/job.py", line 989, in refresh
    data = self.connection.hgetall(self.key)
           ^^^^^^^^^^^^^^^^^^^^^^^^^^^^^^^^^
  File "/home/ubuntu/test-hrms/env/lib/python3.11/site-packages/redis/commands/core.py", line 4887, in hgetall
    return self.execute_command("HGETALL", name)
           ^^^^^^^^^^^^^^^^^^^^^^^^^^^^^^^^^^^^^
  File "/home/ubuntu/test-hrms/env/lib/python3.11/site-packages/redis/client.py", line 1266, in execute_command
    conn = self.connection or pool.get_connection(command_name, **options)
                              ^^^^^^^^^^^^^^^^^^^^^^^^^^^^^^^^^^^^^^^^^^^^
  File "/home/ubuntu/test-hrms/env/lib/python3.11/site-packages/redis/connection.py", line 1457, in get_connection
    connection.connect()
  File "/home/ubuntu/test-hrms/env/lib/python3.11/site-packages/redis/connection.py", line 705, in connect
    raise ConnectionError(self._error_message(e))
redis.exceptions.ConnectionError: Error 111 connecting to 127.0.0.1:11000. Connection refused.
2025-09-14 12:51:44,213 ERROR scheduler Exception in Enqueue Events for Site test-site.local
Traceback (most recent call last):
  File "/home/ubuntu/test-hrms/env/lib/python3.11/site-packages/redis/connection.py", line 699, in connect
    sock = self.retry.call_with_retry(
           ^^^^^^^^^^^^^^^^^^^^^^^^^^^
  File "/home/ubuntu/test-hrms/env/lib/python3.11/site-packages/redis/retry.py", line 46, in call_with_retry
    return do()
           ^^^^
  File "/home/ubuntu/test-hrms/env/lib/python3.11/site-packages/redis/connection.py", line 700, in <lambda>
    lambda: self._connect(), lambda error: self.disconnect(error)
            ^^^^^^^^^^^^^^^
  File "/home/ubuntu/test-hrms/env/lib/python3.11/site-packages/redis/connection.py", line 1002, in _connect
    raise err
  File "/home/ubuntu/test-hrms/env/lib/python3.11/site-packages/redis/connection.py", line 990, in _connect
    sock.connect(socket_address)
ConnectionRefusedError: [Errno 111] Connection refused

During handling of the above exception, another exception occurred:

Traceback (most recent call last):
  File "/home/ubuntu/test-hrms/apps/frappe/frappe/utils/scheduler.py", line 102, in enqueue_events_for_site
    enqueue_events(site=site)
  File "/home/ubuntu/test-hrms/apps/frappe/frappe/utils/scheduler.py", line 122, in enqueue_events
    if job_type.enqueue():
       ^^^^^^^^^^^^^^^^^^
  File "/home/ubuntu/test-hrms/apps/frappe/frappe/core/doctype/scheduled_job_type/scheduled_job_type.py", line 74, in enqueue
    if not self.is_job_in_queue():
           ^^^^^^^^^^^^^^^^^^^^^^
  File "/home/ubuntu/test-hrms/apps/frappe/frappe/core/doctype/scheduled_job_type/scheduled_job_type.py", line 95, in is_job_in_queue
    return is_job_enqueued(self.rq_job_id)
           ^^^^^^^^^^^^^^^^^^^^^^^^^^^^^^^
  File "/home/ubuntu/test-hrms/apps/frappe/frappe/utils/background_jobs.py", line 568, in is_job_enqueued
    return get_job_status(job_id) in (JobStatus.QUEUED, JobStatus.STARTED)
           ^^^^^^^^^^^^^^^^^^^^^^
  File "/home/ubuntu/test-hrms/apps/frappe/frappe/utils/background_jobs.py", line 573, in get_job_status
    job = get_job(job_id)
          ^^^^^^^^^^^^^^^
  File "/home/ubuntu/test-hrms/apps/frappe/frappe/utils/background_jobs.py", line 580, in get_job
    return Job.fetch(create_job_id(job_id), connection=get_redis_conn())
           ^^^^^^^^^^^^^^^^^^^^^^^^^^^^^^^^^^^^^^^^^^^^^^^^^^^^^^^^^^^^^
  File "/home/ubuntu/test-hrms/env/lib/python3.11/site-packages/rq/job.py", line 591, in fetch
    job.refresh()
  File "/home/ubuntu/test-hrms/env/lib/python3.11/site-packages/rq/job.py", line 989, in refresh
    data = self.connection.hgetall(self.key)
           ^^^^^^^^^^^^^^^^^^^^^^^^^^^^^^^^^
  File "/home/ubuntu/test-hrms/env/lib/python3.11/site-packages/redis/commands/core.py", line 4887, in hgetall
    return self.execute_command("HGETALL", name)
           ^^^^^^^^^^^^^^^^^^^^^^^^^^^^^^^^^^^^^
  File "/home/ubuntu/test-hrms/env/lib/python3.11/site-packages/redis/client.py", line 1266, in execute_command
    conn = self.connection or pool.get_connection(command_name, **options)
                              ^^^^^^^^^^^^^^^^^^^^^^^^^^^^^^^^^^^^^^^^^^^^
  File "/home/ubuntu/test-hrms/env/lib/python3.11/site-packages/redis/connection.py", line 1457, in get_connection
    connection.connect()
  File "/home/ubuntu/test-hrms/env/lib/python3.11/site-packages/redis/connection.py", line 705, in connect
    raise ConnectionError(self._error_message(e))
redis.exceptions.ConnectionError: Error 111 connecting to 127.0.0.1:11000. Connection refused.
2025-09-14 12:52:44,299 ERROR scheduler Exception in Enqueue Events for Site test-site.local
Traceback (most recent call last):
  File "/home/ubuntu/test-hrms/env/lib/python3.11/site-packages/redis/connection.py", line 699, in connect
    sock = self.retry.call_with_retry(
           ^^^^^^^^^^^^^^^^^^^^^^^^^^^
  File "/home/ubuntu/test-hrms/env/lib/python3.11/site-packages/redis/retry.py", line 46, in call_with_retry
    return do()
           ^^^^
  File "/home/ubuntu/test-hrms/env/lib/python3.11/site-packages/redis/connection.py", line 700, in <lambda>
    lambda: self._connect(), lambda error: self.disconnect(error)
            ^^^^^^^^^^^^^^^
  File "/home/ubuntu/test-hrms/env/lib/python3.11/site-packages/redis/connection.py", line 1002, in _connect
    raise err
  File "/home/ubuntu/test-hrms/env/lib/python3.11/site-packages/redis/connection.py", line 990, in _connect
    sock.connect(socket_address)
ConnectionRefusedError: [Errno 111] Connection refused

During handling of the above exception, another exception occurred:

Traceback (most recent call last):
  File "/home/ubuntu/test-hrms/apps/frappe/frappe/utils/scheduler.py", line 102, in enqueue_events_for_site
    enqueue_events(site=site)
  File "/home/ubuntu/test-hrms/apps/frappe/frappe/utils/scheduler.py", line 122, in enqueue_events
    if job_type.enqueue():
       ^^^^^^^^^^^^^^^^^^
  File "/home/ubuntu/test-hrms/apps/frappe/frappe/core/doctype/scheduled_job_type/scheduled_job_type.py", line 74, in enqueue
    if not self.is_job_in_queue():
           ^^^^^^^^^^^^^^^^^^^^^^
  File "/home/ubuntu/test-hrms/apps/frappe/frappe/core/doctype/scheduled_job_type/scheduled_job_type.py", line 95, in is_job_in_queue
    return is_job_enqueued(self.rq_job_id)
           ^^^^^^^^^^^^^^^^^^^^^^^^^^^^^^^
  File "/home/ubuntu/test-hrms/apps/frappe/frappe/utils/background_jobs.py", line 568, in is_job_enqueued
    return get_job_status(job_id) in (JobStatus.QUEUED, JobStatus.STARTED)
           ^^^^^^^^^^^^^^^^^^^^^^
  File "/home/ubuntu/test-hrms/apps/frappe/frappe/utils/background_jobs.py", line 573, in get_job_status
    job = get_job(job_id)
          ^^^^^^^^^^^^^^^
  File "/home/ubuntu/test-hrms/apps/frappe/frappe/utils/background_jobs.py", line 580, in get_job
    return Job.fetch(create_job_id(job_id), connection=get_redis_conn())
           ^^^^^^^^^^^^^^^^^^^^^^^^^^^^^^^^^^^^^^^^^^^^^^^^^^^^^^^^^^^^^
  File "/home/ubuntu/test-hrms/env/lib/python3.11/site-packages/rq/job.py", line 591, in fetch
    job.refresh()
  File "/home/ubuntu/test-hrms/env/lib/python3.11/site-packages/rq/job.py", line 989, in refresh
    data = self.connection.hgetall(self.key)
           ^^^^^^^^^^^^^^^^^^^^^^^^^^^^^^^^^
  File "/home/ubuntu/test-hrms/env/lib/python3.11/site-packages/redis/commands/core.py", line 4887, in hgetall
    return self.execute_command("HGETALL", name)
           ^^^^^^^^^^^^^^^^^^^^^^^^^^^^^^^^^^^^^
  File "/home/ubuntu/test-hrms/env/lib/python3.11/site-packages/redis/client.py", line 1266, in execute_command
    conn = self.connection or pool.get_connection(command_name, **options)
                              ^^^^^^^^^^^^^^^^^^^^^^^^^^^^^^^^^^^^^^^^^^^^
  File "/home/ubuntu/test-hrms/env/lib/python3.11/site-packages/redis/connection.py", line 1457, in get_connection
    connection.connect()
  File "/home/ubuntu/test-hrms/env/lib/python3.11/site-packages/redis/connection.py", line 705, in connect
    raise ConnectionError(self._error_message(e))
redis.exceptions.ConnectionError: Error 111 connecting to 127.0.0.1:11000. Connection refused.
2025-09-14 12:53:44,386 ERROR scheduler Exception in Enqueue Events for Site test-site.local
Traceback (most recent call last):
  File "/home/ubuntu/test-hrms/env/lib/python3.11/site-packages/redis/connection.py", line 699, in connect
    sock = self.retry.call_with_retry(
           ^^^^^^^^^^^^^^^^^^^^^^^^^^^
  File "/home/ubuntu/test-hrms/env/lib/python3.11/site-packages/redis/retry.py", line 46, in call_with_retry
    return do()
           ^^^^
  File "/home/ubuntu/test-hrms/env/lib/python3.11/site-packages/redis/connection.py", line 700, in <lambda>
    lambda: self._connect(), lambda error: self.disconnect(error)
            ^^^^^^^^^^^^^^^
  File "/home/ubuntu/test-hrms/env/lib/python3.11/site-packages/redis/connection.py", line 1002, in _connect
    raise err
  File "/home/ubuntu/test-hrms/env/lib/python3.11/site-packages/redis/connection.py", line 990, in _connect
    sock.connect(socket_address)
ConnectionRefusedError: [Errno 111] Connection refused

During handling of the above exception, another exception occurred:

Traceback (most recent call last):
  File "/home/ubuntu/test-hrms/apps/frappe/frappe/utils/scheduler.py", line 102, in enqueue_events_for_site
    enqueue_events(site=site)
  File "/home/ubuntu/test-hrms/apps/frappe/frappe/utils/scheduler.py", line 122, in enqueue_events
    if job_type.enqueue():
       ^^^^^^^^^^^^^^^^^^
  File "/home/ubuntu/test-hrms/apps/frappe/frappe/core/doctype/scheduled_job_type/scheduled_job_type.py", line 74, in enqueue
    if not self.is_job_in_queue():
           ^^^^^^^^^^^^^^^^^^^^^^
  File "/home/ubuntu/test-hrms/apps/frappe/frappe/core/doctype/scheduled_job_type/scheduled_job_type.py", line 95, in is_job_in_queue
    return is_job_enqueued(self.rq_job_id)
           ^^^^^^^^^^^^^^^^^^^^^^^^^^^^^^^
  File "/home/ubuntu/test-hrms/apps/frappe/frappe/utils/background_jobs.py", line 568, in is_job_enqueued
    return get_job_status(job_id) in (JobStatus.QUEUED, JobStatus.STARTED)
           ^^^^^^^^^^^^^^^^^^^^^^
  File "/home/ubuntu/test-hrms/apps/frappe/frappe/utils/background_jobs.py", line 573, in get_job_status
    job = get_job(job_id)
          ^^^^^^^^^^^^^^^
  File "/home/ubuntu/test-hrms/apps/frappe/frappe/utils/background_jobs.py", line 580, in get_job
    return Job.fetch(create_job_id(job_id), connection=get_redis_conn())
           ^^^^^^^^^^^^^^^^^^^^^^^^^^^^^^^^^^^^^^^^^^^^^^^^^^^^^^^^^^^^^
  File "/home/ubuntu/test-hrms/env/lib/python3.11/site-packages/rq/job.py", line 591, in fetch
    job.refresh()
  File "/home/ubuntu/test-hrms/env/lib/python3.11/site-packages/rq/job.py", line 989, in refresh
    data = self.connection.hgetall(self.key)
           ^^^^^^^^^^^^^^^^^^^^^^^^^^^^^^^^^
  File "/home/ubuntu/test-hrms/env/lib/python3.11/site-packages/redis/commands/core.py", line 4887, in hgetall
    return self.execute_command("HGETALL", name)
           ^^^^^^^^^^^^^^^^^^^^^^^^^^^^^^^^^^^^^
  File "/home/ubuntu/test-hrms/env/lib/python3.11/site-packages/redis/client.py", line 1266, in execute_command
    conn = self.connection or pool.get_connection(command_name, **options)
                              ^^^^^^^^^^^^^^^^^^^^^^^^^^^^^^^^^^^^^^^^^^^^
  File "/home/ubuntu/test-hrms/env/lib/python3.11/site-packages/redis/connection.py", line 1457, in get_connection
    connection.connect()
  File "/home/ubuntu/test-hrms/env/lib/python3.11/site-packages/redis/connection.py", line 705, in connect
    raise ConnectionError(self._error_message(e))
redis.exceptions.ConnectionError: Error 111 connecting to 127.0.0.1:11000. Connection refused.
2025-09-14 12:54:44,484 ERROR scheduler Exception in Enqueue Events for Site test-site.local
Traceback (most recent call last):
  File "/home/ubuntu/test-hrms/env/lib/python3.11/site-packages/redis/connection.py", line 699, in connect
    sock = self.retry.call_with_retry(
           ^^^^^^^^^^^^^^^^^^^^^^^^^^^
  File "/home/ubuntu/test-hrms/env/lib/python3.11/site-packages/redis/retry.py", line 46, in call_with_retry
    return do()
           ^^^^
  File "/home/ubuntu/test-hrms/env/lib/python3.11/site-packages/redis/connection.py", line 700, in <lambda>
    lambda: self._connect(), lambda error: self.disconnect(error)
            ^^^^^^^^^^^^^^^
  File "/home/ubuntu/test-hrms/env/lib/python3.11/site-packages/redis/connection.py", line 1002, in _connect
    raise err
  File "/home/ubuntu/test-hrms/env/lib/python3.11/site-packages/redis/connection.py", line 990, in _connect
    sock.connect(socket_address)
ConnectionRefusedError: [Errno 111] Connection refused

During handling of the above exception, another exception occurred:

Traceback (most recent call last):
  File "/home/ubuntu/test-hrms/apps/frappe/frappe/utils/scheduler.py", line 102, in enqueue_events_for_site
    enqueue_events(site=site)
  File "/home/ubuntu/test-hrms/apps/frappe/frappe/utils/scheduler.py", line 122, in enqueue_events
    if job_type.enqueue():
       ^^^^^^^^^^^^^^^^^^
  File "/home/ubuntu/test-hrms/apps/frappe/frappe/core/doctype/scheduled_job_type/scheduled_job_type.py", line 74, in enqueue
    if not self.is_job_in_queue():
           ^^^^^^^^^^^^^^^^^^^^^^
  File "/home/ubuntu/test-hrms/apps/frappe/frappe/core/doctype/scheduled_job_type/scheduled_job_type.py", line 95, in is_job_in_queue
    return is_job_enqueued(self.rq_job_id)
           ^^^^^^^^^^^^^^^^^^^^^^^^^^^^^^^
  File "/home/ubuntu/test-hrms/apps/frappe/frappe/utils/background_jobs.py", line 568, in is_job_enqueued
    return get_job_status(job_id) in (JobStatus.QUEUED, JobStatus.STARTED)
           ^^^^^^^^^^^^^^^^^^^^^^
  File "/home/ubuntu/test-hrms/apps/frappe/frappe/utils/background_jobs.py", line 573, in get_job_status
    job = get_job(job_id)
          ^^^^^^^^^^^^^^^
  File "/home/ubuntu/test-hrms/apps/frappe/frappe/utils/background_jobs.py", line 580, in get_job
    return Job.fetch(create_job_id(job_id), connection=get_redis_conn())
           ^^^^^^^^^^^^^^^^^^^^^^^^^^^^^^^^^^^^^^^^^^^^^^^^^^^^^^^^^^^^^
  File "/home/ubuntu/test-hrms/env/lib/python3.11/site-packages/rq/job.py", line 591, in fetch
    job.refresh()
  File "/home/ubuntu/test-hrms/env/lib/python3.11/site-packages/rq/job.py", line 989, in refresh
    data = self.connection.hgetall(self.key)
           ^^^^^^^^^^^^^^^^^^^^^^^^^^^^^^^^^
  File "/home/ubuntu/test-hrms/env/lib/python3.11/site-packages/redis/commands/core.py", line 4887, in hgetall
    return self.execute_command("HGETALL", name)
           ^^^^^^^^^^^^^^^^^^^^^^^^^^^^^^^^^^^^^
  File "/home/ubuntu/test-hrms/env/lib/python3.11/site-packages/redis/client.py", line 1266, in execute_command
    conn = self.connection or pool.get_connection(command_name, **options)
                              ^^^^^^^^^^^^^^^^^^^^^^^^^^^^^^^^^^^^^^^^^^^^
  File "/home/ubuntu/test-hrms/env/lib/python3.11/site-packages/redis/connection.py", line 1457, in get_connection
    connection.connect()
  File "/home/ubuntu/test-hrms/env/lib/python3.11/site-packages/redis/connection.py", line 705, in connect
    raise ConnectionError(self._error_message(e))
redis.exceptions.ConnectionError: Error 111 connecting to 127.0.0.1:11000. Connection refused.
2025-09-14 13:17:27,108 ERROR scheduler Exception in Enqueue Events for Site test-site.local
Traceback (most recent call last):
  File "/home/ubuntu/test-hrms/env/lib/python3.11/site-packages/redis/connection.py", line 699, in connect
    sock = self.retry.call_with_retry(
           ^^^^^^^^^^^^^^^^^^^^^^^^^^^
  File "/home/ubuntu/test-hrms/env/lib/python3.11/site-packages/redis/retry.py", line 46, in call_with_retry
    return do()
           ^^^^
  File "/home/ubuntu/test-hrms/env/lib/python3.11/site-packages/redis/connection.py", line 700, in <lambda>
    lambda: self._connect(), lambda error: self.disconnect(error)
            ^^^^^^^^^^^^^^^
  File "/home/ubuntu/test-hrms/env/lib/python3.11/site-packages/redis/connection.py", line 1002, in _connect
    raise err
  File "/home/ubuntu/test-hrms/env/lib/python3.11/site-packages/redis/connection.py", line 990, in _connect
    sock.connect(socket_address)
ConnectionRefusedError: [Errno 111] Connection refused

During handling of the above exception, another exception occurred:

Traceback (most recent call last):
  File "/home/ubuntu/test-hrms/apps/frappe/frappe/utils/scheduler.py", line 102, in enqueue_events_for_site
    enqueue_events(site=site)
  File "/home/ubuntu/test-hrms/apps/frappe/frappe/utils/scheduler.py", line 122, in enqueue_events
    if job_type.enqueue():
       ^^^^^^^^^^^^^^^^^^
  File "/home/ubuntu/test-hrms/apps/frappe/frappe/core/doctype/scheduled_job_type/scheduled_job_type.py", line 74, in enqueue
    if not self.is_job_in_queue():
           ^^^^^^^^^^^^^^^^^^^^^^
  File "/home/ubuntu/test-hrms/apps/frappe/frappe/core/doctype/scheduled_job_type/scheduled_job_type.py", line 95, in is_job_in_queue
    return is_job_enqueued(self.rq_job_id)
           ^^^^^^^^^^^^^^^^^^^^^^^^^^^^^^^
  File "/home/ubuntu/test-hrms/apps/frappe/frappe/utils/background_jobs.py", line 568, in is_job_enqueued
    return get_job_status(job_id) in (JobStatus.QUEUED, JobStatus.STARTED)
           ^^^^^^^^^^^^^^^^^^^^^^
  File "/home/ubuntu/test-hrms/apps/frappe/frappe/utils/background_jobs.py", line 573, in get_job_status
    job = get_job(job_id)
          ^^^^^^^^^^^^^^^
  File "/home/ubuntu/test-hrms/apps/frappe/frappe/utils/background_jobs.py", line 580, in get_job
    return Job.fetch(create_job_id(job_id), connection=get_redis_conn())
           ^^^^^^^^^^^^^^^^^^^^^^^^^^^^^^^^^^^^^^^^^^^^^^^^^^^^^^^^^^^^^
  File "/home/ubuntu/test-hrms/env/lib/python3.11/site-packages/rq/job.py", line 591, in fetch
    job.refresh()
  File "/home/ubuntu/test-hrms/env/lib/python3.11/site-packages/rq/job.py", line 989, in refresh
    data = self.connection.hgetall(self.key)
           ^^^^^^^^^^^^^^^^^^^^^^^^^^^^^^^^^
  File "/home/ubuntu/test-hrms/env/lib/python3.11/site-packages/redis/commands/core.py", line 4887, in hgetall
    return self.execute_command("HGETALL", name)
           ^^^^^^^^^^^^^^^^^^^^^^^^^^^^^^^^^^^^^
  File "/home/ubuntu/test-hrms/env/lib/python3.11/site-packages/redis/client.py", line 1266, in execute_command
    conn = self.connection or pool.get_connection(command_name, **options)
                              ^^^^^^^^^^^^^^^^^^^^^^^^^^^^^^^^^^^^^^^^^^^^
  File "/home/ubuntu/test-hrms/env/lib/python3.11/site-packages/redis/connection.py", line 1457, in get_connection
    connection.connect()
  File "/home/ubuntu/test-hrms/env/lib/python3.11/site-packages/redis/connection.py", line 705, in connect
    raise ConnectionError(self._error_message(e))
redis.exceptions.ConnectionError: Error 111 connecting to 127.0.0.1:11000. Connection refused.
2025-09-14 13:18:26,835 ERROR scheduler Exception in Enqueue Events for Site test-site.local
Traceback (most recent call last):
  File "/home/ubuntu/test-hrms/env/lib/python3.11/site-packages/redis/connection.py", line 699, in connect
    sock = self.retry.call_with_retry(
           ^^^^^^^^^^^^^^^^^^^^^^^^^^^
  File "/home/ubuntu/test-hrms/env/lib/python3.11/site-packages/redis/retry.py", line 46, in call_with_retry
    return do()
           ^^^^
  File "/home/ubuntu/test-hrms/env/lib/python3.11/site-packages/redis/connection.py", line 700, in <lambda>
    lambda: self._connect(), lambda error: self.disconnect(error)
            ^^^^^^^^^^^^^^^
  File "/home/ubuntu/test-hrms/env/lib/python3.11/site-packages/redis/connection.py", line 1002, in _connect
    raise err
  File "/home/ubuntu/test-hrms/env/lib/python3.11/site-packages/redis/connection.py", line 990, in _connect
    sock.connect(socket_address)
ConnectionRefusedError: [Errno 111] Connection refused

During handling of the above exception, another exception occurred:

Traceback (most recent call last):
  File "/home/ubuntu/test-hrms/apps/frappe/frappe/utils/scheduler.py", line 102, in enqueue_events_for_site
    enqueue_events(site=site)
  File "/home/ubuntu/test-hrms/apps/frappe/frappe/utils/scheduler.py", line 122, in enqueue_events
    if job_type.enqueue():
       ^^^^^^^^^^^^^^^^^^
  File "/home/ubuntu/test-hrms/apps/frappe/frappe/core/doctype/scheduled_job_type/scheduled_job_type.py", line 74, in enqueue
    if not self.is_job_in_queue():
           ^^^^^^^^^^^^^^^^^^^^^^
  File "/home/ubuntu/test-hrms/apps/frappe/frappe/core/doctype/scheduled_job_type/scheduled_job_type.py", line 95, in is_job_in_queue
    return is_job_enqueued(self.rq_job_id)
           ^^^^^^^^^^^^^^^^^^^^^^^^^^^^^^^
  File "/home/ubuntu/test-hrms/apps/frappe/frappe/utils/background_jobs.py", line 568, in is_job_enqueued
    return get_job_status(job_id) in (JobStatus.QUEUED, JobStatus.STARTED)
           ^^^^^^^^^^^^^^^^^^^^^^
  File "/home/ubuntu/test-hrms/apps/frappe/frappe/utils/background_jobs.py", line 573, in get_job_status
    job = get_job(job_id)
          ^^^^^^^^^^^^^^^
  File "/home/ubuntu/test-hrms/apps/frappe/frappe/utils/background_jobs.py", line 580, in get_job
    return Job.fetch(create_job_id(job_id), connection=get_redis_conn())
           ^^^^^^^^^^^^^^^^^^^^^^^^^^^^^^^^^^^^^^^^^^^^^^^^^^^^^^^^^^^^^
  File "/home/ubuntu/test-hrms/env/lib/python3.11/site-packages/rq/job.py", line 591, in fetch
    job.refresh()
  File "/home/ubuntu/test-hrms/env/lib/python3.11/site-packages/rq/job.py", line 989, in refresh
    data = self.connection.hgetall(self.key)
           ^^^^^^^^^^^^^^^^^^^^^^^^^^^^^^^^^
  File "/home/ubuntu/test-hrms/env/lib/python3.11/site-packages/redis/commands/core.py", line 4887, in hgetall
    return self.execute_command("HGETALL", name)
           ^^^^^^^^^^^^^^^^^^^^^^^^^^^^^^^^^^^^^
  File "/home/ubuntu/test-hrms/env/lib/python3.11/site-packages/redis/client.py", line 1266, in execute_command
    conn = self.connection or pool.get_connection(command_name, **options)
                              ^^^^^^^^^^^^^^^^^^^^^^^^^^^^^^^^^^^^^^^^^^^^
  File "/home/ubuntu/test-hrms/env/lib/python3.11/site-packages/redis/connection.py", line 1457, in get_connection
    connection.connect()
  File "/home/ubuntu/test-hrms/env/lib/python3.11/site-packages/redis/connection.py", line 705, in connect
    raise ConnectionError(self._error_message(e))
redis.exceptions.ConnectionError: Error 111 connecting to 127.0.0.1:11000. Connection refused.
2025-09-14 13:19:26,925 ERROR scheduler Exception in Enqueue Events for Site test-site.local
Traceback (most recent call last):
  File "/home/ubuntu/test-hrms/env/lib/python3.11/site-packages/redis/connection.py", line 699, in connect
    sock = self.retry.call_with_retry(
           ^^^^^^^^^^^^^^^^^^^^^^^^^^^
  File "/home/ubuntu/test-hrms/env/lib/python3.11/site-packages/redis/retry.py", line 46, in call_with_retry
    return do()
           ^^^^
  File "/home/ubuntu/test-hrms/env/lib/python3.11/site-packages/redis/connection.py", line 700, in <lambda>
    lambda: self._connect(), lambda error: self.disconnect(error)
            ^^^^^^^^^^^^^^^
  File "/home/ubuntu/test-hrms/env/lib/python3.11/site-packages/redis/connection.py", line 1002, in _connect
    raise err
  File "/home/ubuntu/test-hrms/env/lib/python3.11/site-packages/redis/connection.py", line 990, in _connect
    sock.connect(socket_address)
ConnectionRefusedError: [Errno 111] Connection refused

During handling of the above exception, another exception occurred:

Traceback (most recent call last):
  File "/home/ubuntu/test-hrms/apps/frappe/frappe/utils/scheduler.py", line 102, in enqueue_events_for_site
    enqueue_events(site=site)
  File "/home/ubuntu/test-hrms/apps/frappe/frappe/utils/scheduler.py", line 122, in enqueue_events
    if job_type.enqueue():
       ^^^^^^^^^^^^^^^^^^
  File "/home/ubuntu/test-hrms/apps/frappe/frappe/core/doctype/scheduled_job_type/scheduled_job_type.py", line 74, in enqueue
    if not self.is_job_in_queue():
           ^^^^^^^^^^^^^^^^^^^^^^
  File "/home/ubuntu/test-hrms/apps/frappe/frappe/core/doctype/scheduled_job_type/scheduled_job_type.py", line 95, in is_job_in_queue
    return is_job_enqueued(self.rq_job_id)
           ^^^^^^^^^^^^^^^^^^^^^^^^^^^^^^^
  File "/home/ubuntu/test-hrms/apps/frappe/frappe/utils/background_jobs.py", line 568, in is_job_enqueued
    return get_job_status(job_id) in (JobStatus.QUEUED, JobStatus.STARTED)
           ^^^^^^^^^^^^^^^^^^^^^^
  File "/home/ubuntu/test-hrms/apps/frappe/frappe/utils/background_jobs.py", line 573, in get_job_status
    job = get_job(job_id)
          ^^^^^^^^^^^^^^^
  File "/home/ubuntu/test-hrms/apps/frappe/frappe/utils/background_jobs.py", line 580, in get_job
    return Job.fetch(create_job_id(job_id), connection=get_redis_conn())
           ^^^^^^^^^^^^^^^^^^^^^^^^^^^^^^^^^^^^^^^^^^^^^^^^^^^^^^^^^^^^^
  File "/home/ubuntu/test-hrms/env/lib/python3.11/site-packages/rq/job.py", line 591, in fetch
    job.refresh()
  File "/home/ubuntu/test-hrms/env/lib/python3.11/site-packages/rq/job.py", line 989, in refresh
    data = self.connection.hgetall(self.key)
           ^^^^^^^^^^^^^^^^^^^^^^^^^^^^^^^^^
  File "/home/ubuntu/test-hrms/env/lib/python3.11/site-packages/redis/commands/core.py", line 4887, in hgetall
    return self.execute_command("HGETALL", name)
           ^^^^^^^^^^^^^^^^^^^^^^^^^^^^^^^^^^^^^
  File "/home/ubuntu/test-hrms/env/lib/python3.11/site-packages/redis/client.py", line 1266, in execute_command
    conn = self.connection or pool.get_connection(command_name, **options)
                              ^^^^^^^^^^^^^^^^^^^^^^^^^^^^^^^^^^^^^^^^^^^^
  File "/home/ubuntu/test-hrms/env/lib/python3.11/site-packages/redis/connection.py", line 1457, in get_connection
    connection.connect()
  File "/home/ubuntu/test-hrms/env/lib/python3.11/site-packages/redis/connection.py", line 705, in connect
    raise ConnectionError(self._error_message(e))
redis.exceptions.ConnectionError: Error 111 connecting to 127.0.0.1:11000. Connection refused.
2025-09-14 13:20:27,013 ERROR scheduler Exception in Enqueue Events for Site test-site.local
Traceback (most recent call last):
  File "/home/ubuntu/test-hrms/env/lib/python3.11/site-packages/redis/connection.py", line 699, in connect
    sock = self.retry.call_with_retry(
           ^^^^^^^^^^^^^^^^^^^^^^^^^^^
  File "/home/ubuntu/test-hrms/env/lib/python3.11/site-packages/redis/retry.py", line 46, in call_with_retry
    return do()
           ^^^^
  File "/home/ubuntu/test-hrms/env/lib/python3.11/site-packages/redis/connection.py", line 700, in <lambda>
    lambda: self._connect(), lambda error: self.disconnect(error)
            ^^^^^^^^^^^^^^^
  File "/home/ubuntu/test-hrms/env/lib/python3.11/site-packages/redis/connection.py", line 1002, in _connect
    raise err
  File "/home/ubuntu/test-hrms/env/lib/python3.11/site-packages/redis/connection.py", line 990, in _connect
    sock.connect(socket_address)
ConnectionRefusedError: [Errno 111] Connection refused

During handling of the above exception, another exception occurred:

Traceback (most recent call last):
  File "/home/ubuntu/test-hrms/apps/frappe/frappe/utils/scheduler.py", line 102, in enqueue_events_for_site
    enqueue_events(site=site)
  File "/home/ubuntu/test-hrms/apps/frappe/frappe/utils/scheduler.py", line 122, in enqueue_events
    if job_type.enqueue():
       ^^^^^^^^^^^^^^^^^^
  File "/home/ubuntu/test-hrms/apps/frappe/frappe/core/doctype/scheduled_job_type/scheduled_job_type.py", line 74, in enqueue
    if not self.is_job_in_queue():
           ^^^^^^^^^^^^^^^^^^^^^^
  File "/home/ubuntu/test-hrms/apps/frappe/frappe/core/doctype/scheduled_job_type/scheduled_job_type.py", line 95, in is_job_in_queue
    return is_job_enqueued(self.rq_job_id)
           ^^^^^^^^^^^^^^^^^^^^^^^^^^^^^^^
  File "/home/ubuntu/test-hrms/apps/frappe/frappe/utils/background_jobs.py", line 568, in is_job_enqueued
    return get_job_status(job_id) in (JobStatus.QUEUED, JobStatus.STARTED)
           ^^^^^^^^^^^^^^^^^^^^^^
  File "/home/ubuntu/test-hrms/apps/frappe/frappe/utils/background_jobs.py", line 573, in get_job_status
    job = get_job(job_id)
          ^^^^^^^^^^^^^^^
  File "/home/ubuntu/test-hrms/apps/frappe/frappe/utils/background_jobs.py", line 580, in get_job
    return Job.fetch(create_job_id(job_id), connection=get_redis_conn())
           ^^^^^^^^^^^^^^^^^^^^^^^^^^^^^^^^^^^^^^^^^^^^^^^^^^^^^^^^^^^^^
  File "/home/ubuntu/test-hrms/env/lib/python3.11/site-packages/rq/job.py", line 591, in fetch
    job.refresh()
  File "/home/ubuntu/test-hrms/env/lib/python3.11/site-packages/rq/job.py", line 989, in refresh
    data = self.connection.hgetall(self.key)
           ^^^^^^^^^^^^^^^^^^^^^^^^^^^^^^^^^
  File "/home/ubuntu/test-hrms/env/lib/python3.11/site-packages/redis/commands/core.py", line 4887, in hgetall
    return self.execute_command("HGETALL", name)
           ^^^^^^^^^^^^^^^^^^^^^^^^^^^^^^^^^^^^^
  File "/home/ubuntu/test-hrms/env/lib/python3.11/site-packages/redis/client.py", line 1266, in execute_command
    conn = self.connection or pool.get_connection(command_name, **options)
                              ^^^^^^^^^^^^^^^^^^^^^^^^^^^^^^^^^^^^^^^^^^^^
  File "/home/ubuntu/test-hrms/env/lib/python3.11/site-packages/redis/connection.py", line 1457, in get_connection
    connection.connect()
  File "/home/ubuntu/test-hrms/env/lib/python3.11/site-packages/redis/connection.py", line 705, in connect
    raise ConnectionError(self._error_message(e))
redis.exceptions.ConnectionError: Error 111 connecting to 127.0.0.1:11000. Connection refused.
2025-09-14 13:21:27,098 ERROR scheduler Exception in Enqueue Events for Site test-site.local
Traceback (most recent call last):
  File "/home/ubuntu/test-hrms/env/lib/python3.11/site-packages/redis/connection.py", line 699, in connect
    sock = self.retry.call_with_retry(
           ^^^^^^^^^^^^^^^^^^^^^^^^^^^
  File "/home/ubuntu/test-hrms/env/lib/python3.11/site-packages/redis/retry.py", line 46, in call_with_retry
    return do()
           ^^^^
  File "/home/ubuntu/test-hrms/env/lib/python3.11/site-packages/redis/connection.py", line 700, in <lambda>
    lambda: self._connect(), lambda error: self.disconnect(error)
            ^^^^^^^^^^^^^^^
  File "/home/ubuntu/test-hrms/env/lib/python3.11/site-packages/redis/connection.py", line 1002, in _connect
    raise err
  File "/home/ubuntu/test-hrms/env/lib/python3.11/site-packages/redis/connection.py", line 990, in _connect
    sock.connect(socket_address)
ConnectionRefusedError: [Errno 111] Connection refused

During handling of the above exception, another exception occurred:

Traceback (most recent call last):
  File "/home/ubuntu/test-hrms/apps/frappe/frappe/utils/scheduler.py", line 102, in enqueue_events_for_site
    enqueue_events(site=site)
  File "/home/ubuntu/test-hrms/apps/frappe/frappe/utils/scheduler.py", line 122, in enqueue_events
    if job_type.enqueue():
       ^^^^^^^^^^^^^^^^^^
  File "/home/ubuntu/test-hrms/apps/frappe/frappe/core/doctype/scheduled_job_type/scheduled_job_type.py", line 74, in enqueue
    if not self.is_job_in_queue():
           ^^^^^^^^^^^^^^^^^^^^^^
  File "/home/ubuntu/test-hrms/apps/frappe/frappe/core/doctype/scheduled_job_type/scheduled_job_type.py", line 95, in is_job_in_queue
    return is_job_enqueued(self.rq_job_id)
           ^^^^^^^^^^^^^^^^^^^^^^^^^^^^^^^
  File "/home/ubuntu/test-hrms/apps/frappe/frappe/utils/background_jobs.py", line 568, in is_job_enqueued
    return get_job_status(job_id) in (JobStatus.QUEUED, JobStatus.STARTED)
           ^^^^^^^^^^^^^^^^^^^^^^
  File "/home/ubuntu/test-hrms/apps/frappe/frappe/utils/background_jobs.py", line 573, in get_job_status
    job = get_job(job_id)
          ^^^^^^^^^^^^^^^
  File "/home/ubuntu/test-hrms/apps/frappe/frappe/utils/background_jobs.py", line 580, in get_job
    return Job.fetch(create_job_id(job_id), connection=get_redis_conn())
           ^^^^^^^^^^^^^^^^^^^^^^^^^^^^^^^^^^^^^^^^^^^^^^^^^^^^^^^^^^^^^
  File "/home/ubuntu/test-hrms/env/lib/python3.11/site-packages/rq/job.py", line 591, in fetch
    job.refresh()
  File "/home/ubuntu/test-hrms/env/lib/python3.11/site-packages/rq/job.py", line 989, in refresh
    data = self.connection.hgetall(self.key)
           ^^^^^^^^^^^^^^^^^^^^^^^^^^^^^^^^^
  File "/home/ubuntu/test-hrms/env/lib/python3.11/site-packages/redis/commands/core.py", line 4887, in hgetall
    return self.execute_command("HGETALL", name)
           ^^^^^^^^^^^^^^^^^^^^^^^^^^^^^^^^^^^^^
  File "/home/ubuntu/test-hrms/env/lib/python3.11/site-packages/redis/client.py", line 1266, in execute_command
    conn = self.connection or pool.get_connection(command_name, **options)
                              ^^^^^^^^^^^^^^^^^^^^^^^^^^^^^^^^^^^^^^^^^^^^
  File "/home/ubuntu/test-hrms/env/lib/python3.11/site-packages/redis/connection.py", line 1457, in get_connection
    connection.connect()
  File "/home/ubuntu/test-hrms/env/lib/python3.11/site-packages/redis/connection.py", line 705, in connect
    raise ConnectionError(self._error_message(e))
redis.exceptions.ConnectionError: Error 111 connecting to 127.0.0.1:11000. Connection refused.
2025-09-14 13:22:27,191 ERROR scheduler Exception in Enqueue Events for Site test-site.local
Traceback (most recent call last):
  File "/home/ubuntu/test-hrms/env/lib/python3.11/site-packages/redis/connection.py", line 699, in connect
    sock = self.retry.call_with_retry(
           ^^^^^^^^^^^^^^^^^^^^^^^^^^^
  File "/home/ubuntu/test-hrms/env/lib/python3.11/site-packages/redis/retry.py", line 46, in call_with_retry
    return do()
           ^^^^
  File "/home/ubuntu/test-hrms/env/lib/python3.11/site-packages/redis/connection.py", line 700, in <lambda>
    lambda: self._connect(), lambda error: self.disconnect(error)
            ^^^^^^^^^^^^^^^
  File "/home/ubuntu/test-hrms/env/lib/python3.11/site-packages/redis/connection.py", line 1002, in _connect
    raise err
  File "/home/ubuntu/test-hrms/env/lib/python3.11/site-packages/redis/connection.py", line 990, in _connect
    sock.connect(socket_address)
ConnectionRefusedError: [Errno 111] Connection refused

During handling of the above exception, another exception occurred:

Traceback (most recent call last):
  File "/home/ubuntu/test-hrms/apps/frappe/frappe/utils/scheduler.py", line 102, in enqueue_events_for_site
    enqueue_events(site=site)
  File "/home/ubuntu/test-hrms/apps/frappe/frappe/utils/scheduler.py", line 122, in enqueue_events
    if job_type.enqueue():
       ^^^^^^^^^^^^^^^^^^
  File "/home/ubuntu/test-hrms/apps/frappe/frappe/core/doctype/scheduled_job_type/scheduled_job_type.py", line 74, in enqueue
    if not self.is_job_in_queue():
           ^^^^^^^^^^^^^^^^^^^^^^
  File "/home/ubuntu/test-hrms/apps/frappe/frappe/core/doctype/scheduled_job_type/scheduled_job_type.py", line 95, in is_job_in_queue
    return is_job_enqueued(self.rq_job_id)
           ^^^^^^^^^^^^^^^^^^^^^^^^^^^^^^^
  File "/home/ubuntu/test-hrms/apps/frappe/frappe/utils/background_jobs.py", line 568, in is_job_enqueued
    return get_job_status(job_id) in (JobStatus.QUEUED, JobStatus.STARTED)
           ^^^^^^^^^^^^^^^^^^^^^^
  File "/home/ubuntu/test-hrms/apps/frappe/frappe/utils/background_jobs.py", line 573, in get_job_status
    job = get_job(job_id)
          ^^^^^^^^^^^^^^^
  File "/home/ubuntu/test-hrms/apps/frappe/frappe/utils/background_jobs.py", line 580, in get_job
    return Job.fetch(create_job_id(job_id), connection=get_redis_conn())
           ^^^^^^^^^^^^^^^^^^^^^^^^^^^^^^^^^^^^^^^^^^^^^^^^^^^^^^^^^^^^^
  File "/home/ubuntu/test-hrms/env/lib/python3.11/site-packages/rq/job.py", line 591, in fetch
    job.refresh()
  File "/home/ubuntu/test-hrms/env/lib/python3.11/site-packages/rq/job.py", line 989, in refresh
    data = self.connection.hgetall(self.key)
           ^^^^^^^^^^^^^^^^^^^^^^^^^^^^^^^^^
  File "/home/ubuntu/test-hrms/env/lib/python3.11/site-packages/redis/commands/core.py", line 4887, in hgetall
    return self.execute_command("HGETALL", name)
           ^^^^^^^^^^^^^^^^^^^^^^^^^^^^^^^^^^^^^
  File "/home/ubuntu/test-hrms/env/lib/python3.11/site-packages/redis/client.py", line 1266, in execute_command
    conn = self.connection or pool.get_connection(command_name, **options)
                              ^^^^^^^^^^^^^^^^^^^^^^^^^^^^^^^^^^^^^^^^^^^^
  File "/home/ubuntu/test-hrms/env/lib/python3.11/site-packages/redis/connection.py", line 1457, in get_connection
    connection.connect()
  File "/home/ubuntu/test-hrms/env/lib/python3.11/site-packages/redis/connection.py", line 705, in connect
    raise ConnectionError(self._error_message(e))
redis.exceptions.ConnectionError: Error 111 connecting to 127.0.0.1:11000. Connection refused.
2025-09-14 13:23:27,277 ERROR scheduler Exception in Enqueue Events for Site test-site.local
Traceback (most recent call last):
  File "/home/ubuntu/test-hrms/env/lib/python3.11/site-packages/redis/connection.py", line 699, in connect
    sock = self.retry.call_with_retry(
           ^^^^^^^^^^^^^^^^^^^^^^^^^^^
  File "/home/ubuntu/test-hrms/env/lib/python3.11/site-packages/redis/retry.py", line 46, in call_with_retry
    return do()
           ^^^^
  File "/home/ubuntu/test-hrms/env/lib/python3.11/site-packages/redis/connection.py", line 700, in <lambda>
    lambda: self._connect(), lambda error: self.disconnect(error)
            ^^^^^^^^^^^^^^^
  File "/home/ubuntu/test-hrms/env/lib/python3.11/site-packages/redis/connection.py", line 1002, in _connect
    raise err
  File "/home/ubuntu/test-hrms/env/lib/python3.11/site-packages/redis/connection.py", line 990, in _connect
    sock.connect(socket_address)
ConnectionRefusedError: [Errno 111] Connection refused

During handling of the above exception, another exception occurred:

Traceback (most recent call last):
  File "/home/ubuntu/test-hrms/apps/frappe/frappe/utils/scheduler.py", line 102, in enqueue_events_for_site
    enqueue_events(site=site)
  File "/home/ubuntu/test-hrms/apps/frappe/frappe/utils/scheduler.py", line 122, in enqueue_events
    if job_type.enqueue():
       ^^^^^^^^^^^^^^^^^^
  File "/home/ubuntu/test-hrms/apps/frappe/frappe/core/doctype/scheduled_job_type/scheduled_job_type.py", line 74, in enqueue
    if not self.is_job_in_queue():
           ^^^^^^^^^^^^^^^^^^^^^^
  File "/home/ubuntu/test-hrms/apps/frappe/frappe/core/doctype/scheduled_job_type/scheduled_job_type.py", line 95, in is_job_in_queue
    return is_job_enqueued(self.rq_job_id)
           ^^^^^^^^^^^^^^^^^^^^^^^^^^^^^^^
  File "/home/ubuntu/test-hrms/apps/frappe/frappe/utils/background_jobs.py", line 568, in is_job_enqueued
    return get_job_status(job_id) in (JobStatus.QUEUED, JobStatus.STARTED)
           ^^^^^^^^^^^^^^^^^^^^^^
  File "/home/ubuntu/test-hrms/apps/frappe/frappe/utils/background_jobs.py", line 573, in get_job_status
    job = get_job(job_id)
          ^^^^^^^^^^^^^^^
  File "/home/ubuntu/test-hrms/apps/frappe/frappe/utils/background_jobs.py", line 580, in get_job
    return Job.fetch(create_job_id(job_id), connection=get_redis_conn())
           ^^^^^^^^^^^^^^^^^^^^^^^^^^^^^^^^^^^^^^^^^^^^^^^^^^^^^^^^^^^^^
  File "/home/ubuntu/test-hrms/env/lib/python3.11/site-packages/rq/job.py", line 591, in fetch
    job.refresh()
  File "/home/ubuntu/test-hrms/env/lib/python3.11/site-packages/rq/job.py", line 989, in refresh
    data = self.connection.hgetall(self.key)
           ^^^^^^^^^^^^^^^^^^^^^^^^^^^^^^^^^
  File "/home/ubuntu/test-hrms/env/lib/python3.11/site-packages/redis/commands/core.py", line 4887, in hgetall
    return self.execute_command("HGETALL", name)
           ^^^^^^^^^^^^^^^^^^^^^^^^^^^^^^^^^^^^^
  File "/home/ubuntu/test-hrms/env/lib/python3.11/site-packages/redis/client.py", line 1266, in execute_command
    conn = self.connection or pool.get_connection(command_name, **options)
                              ^^^^^^^^^^^^^^^^^^^^^^^^^^^^^^^^^^^^^^^^^^^^
  File "/home/ubuntu/test-hrms/env/lib/python3.11/site-packages/redis/connection.py", line 1457, in get_connection
    connection.connect()
  File "/home/ubuntu/test-hrms/env/lib/python3.11/site-packages/redis/connection.py", line 705, in connect
    raise ConnectionError(self._error_message(e))
redis.exceptions.ConnectionError: Error 111 connecting to 127.0.0.1:11000. Connection refused.
2025-09-14 13:24:27,362 ERROR scheduler Exception in Enqueue Events for Site test-site.local
Traceback (most recent call last):
  File "/home/ubuntu/test-hrms/env/lib/python3.11/site-packages/redis/connection.py", line 699, in connect
    sock = self.retry.call_with_retry(
           ^^^^^^^^^^^^^^^^^^^^^^^^^^^
  File "/home/ubuntu/test-hrms/env/lib/python3.11/site-packages/redis/retry.py", line 46, in call_with_retry
    return do()
           ^^^^
  File "/home/ubuntu/test-hrms/env/lib/python3.11/site-packages/redis/connection.py", line 700, in <lambda>
    lambda: self._connect(), lambda error: self.disconnect(error)
            ^^^^^^^^^^^^^^^
  File "/home/ubuntu/test-hrms/env/lib/python3.11/site-packages/redis/connection.py", line 1002, in _connect
    raise err
  File "/home/ubuntu/test-hrms/env/lib/python3.11/site-packages/redis/connection.py", line 990, in _connect
    sock.connect(socket_address)
ConnectionRefusedError: [Errno 111] Connection refused

During handling of the above exception, another exception occurred:

Traceback (most recent call last):
  File "/home/ubuntu/test-hrms/apps/frappe/frappe/utils/scheduler.py", line 102, in enqueue_events_for_site
    enqueue_events(site=site)
  File "/home/ubuntu/test-hrms/apps/frappe/frappe/utils/scheduler.py", line 122, in enqueue_events
    if job_type.enqueue():
       ^^^^^^^^^^^^^^^^^^
  File "/home/ubuntu/test-hrms/apps/frappe/frappe/core/doctype/scheduled_job_type/scheduled_job_type.py", line 74, in enqueue
    if not self.is_job_in_queue():
           ^^^^^^^^^^^^^^^^^^^^^^
  File "/home/ubuntu/test-hrms/apps/frappe/frappe/core/doctype/scheduled_job_type/scheduled_job_type.py", line 95, in is_job_in_queue
    return is_job_enqueued(self.rq_job_id)
           ^^^^^^^^^^^^^^^^^^^^^^^^^^^^^^^
  File "/home/ubuntu/test-hrms/apps/frappe/frappe/utils/background_jobs.py", line 568, in is_job_enqueued
    return get_job_status(job_id) in (JobStatus.QUEUED, JobStatus.STARTED)
           ^^^^^^^^^^^^^^^^^^^^^^
  File "/home/ubuntu/test-hrms/apps/frappe/frappe/utils/background_jobs.py", line 573, in get_job_status
    job = get_job(job_id)
          ^^^^^^^^^^^^^^^
  File "/home/ubuntu/test-hrms/apps/frappe/frappe/utils/background_jobs.py", line 580, in get_job
    return Job.fetch(create_job_id(job_id), connection=get_redis_conn())
           ^^^^^^^^^^^^^^^^^^^^^^^^^^^^^^^^^^^^^^^^^^^^^^^^^^^^^^^^^^^^^
  File "/home/ubuntu/test-hrms/env/lib/python3.11/site-packages/rq/job.py", line 591, in fetch
    job.refresh()
  File "/home/ubuntu/test-hrms/env/lib/python3.11/site-packages/rq/job.py", line 989, in refresh
    data = self.connection.hgetall(self.key)
           ^^^^^^^^^^^^^^^^^^^^^^^^^^^^^^^^^
  File "/home/ubuntu/test-hrms/env/lib/python3.11/site-packages/redis/commands/core.py", line 4887, in hgetall
    return self.execute_command("HGETALL", name)
           ^^^^^^^^^^^^^^^^^^^^^^^^^^^^^^^^^^^^^
  File "/home/ubuntu/test-hrms/env/lib/python3.11/site-packages/redis/client.py", line 1266, in execute_command
    conn = self.connection or pool.get_connection(command_name, **options)
                              ^^^^^^^^^^^^^^^^^^^^^^^^^^^^^^^^^^^^^^^^^^^^
  File "/home/ubuntu/test-hrms/env/lib/python3.11/site-packages/redis/connection.py", line 1457, in get_connection
    connection.connect()
  File "/home/ubuntu/test-hrms/env/lib/python3.11/site-packages/redis/connection.py", line 705, in connect
    raise ConnectionError(self._error_message(e))
redis.exceptions.ConnectionError: Error 111 connecting to 127.0.0.1:11000. Connection refused.
