2025-09-14 12:20:41,192 ERROR scheduler Exception in Enqueue Events for Site test-site.local
Traceback (most recent call last):
  File "/home/ubuntu/test-hrms/env/lib/python3.11/site-packages/redis/connection.py", line 1463, in get_connection
    if connection.can_read():
       ^^^^^^^^^^^^^^^^^^^^^
  File "/home/ubuntu/test-hrms/env/lib/python3.11/site-packages/redis/connection.py", line 861, in can_read
    return self._parser.can_read(timeout)
           ^^^^^^^^^^^^^^^^^^^^^^^^^^^^^^
  File "/home/ubuntu/test-hrms/env/lib/python3.11/site-packages/redis/connection.py", line 444, in can_read
    return self.read_from_socket(timeout=timeout, raise_on_timeout=False)
           ^^^^^^^^^^^^^^^^^^^^^^^^^^^^^^^^^^^^^^^^^^^^^^^^^^^^^^^^^^^^^^
  File "/home/ubuntu/test-hrms/env/lib/python3.11/site-packages/redis/connection.py", line 455, in read_from_socket
    raise ConnectionError(SERVER_CLOSED_CONNECTION_ERROR)
redis.exceptions.ConnectionError: Connection closed by server.

During handling of the above exception, another exception occurred:

Traceback (most recent call last):
  File "/home/ubuntu/test-hrms/env/lib/python3.11/site-packages/redis/connection.py", line 699, in connect
    sock = self.retry.call_with_retry(
           ^^^^^^^^^^^^^^^^^^^^^^^^^^^
  File "/home/ubuntu/test-hrms/env/lib/python3.11/site-packages/redis/retry.py", line 46, in call_with_retry
    return do()
           ^^^^
  File "/home/ubuntu/test-hrms/env/lib/python3.11/site-packages/redis/connection.py", line 700, in <lambda>
    lambda: self._connect(), lambda error: self.disconnect(error)
            ^^^^^^^^^^^^^^^
  File "/home/ubuntu/test-hrms/env/lib/python3.11/site-packages/redis/connection.py", line 1002, in _connect
    raise err
  File "/home/ubuntu/test-hrms/env/lib/python3.11/site-packages/redis/connection.py", line 990, in _connect
    sock.connect(socket_address)
ConnectionRefusedError: [Errno 111] Connection refused

During handling of the above exception, another exception occurred:

Traceback (most recent call last):
  File "/home/ubuntu/test-hrms/apps/frappe/frappe/utils/scheduler.py", line 102, in enqueue_events_for_site
    enqueue_events(site=site)
  File "/home/ubuntu/test-hrms/apps/frappe/frappe/utils/scheduler.py", line 122, in enqueue_events
    if job_type.enqueue():
       ^^^^^^^^^^^^^^^^^^
  File "/home/ubuntu/test-hrms/apps/frappe/frappe/core/doctype/scheduled_job_type/scheduled_job_type.py", line 74, in enqueue
    if not self.is_job_in_queue():
           ^^^^^^^^^^^^^^^^^^^^^^
  File "/home/ubuntu/test-hrms/apps/frappe/frappe/core/doctype/scheduled_job_type/scheduled_job_type.py", line 95, in is_job_in_queue
    return is_job_enqueued(self.rq_job_id)
           ^^^^^^^^^^^^^^^^^^^^^^^^^^^^^^^
  File "/home/ubuntu/test-hrms/apps/frappe/frappe/utils/background_jobs.py", line 568, in is_job_enqueued
    return get_job_status(job_id) in (JobStatus.QUEUED, JobStatus.STARTED)
           ^^^^^^^^^^^^^^^^^^^^^^
  File "/home/ubuntu/test-hrms/apps/frappe/frappe/utils/background_jobs.py", line 573, in get_job_status
    job = get_job(job_id)
          ^^^^^^^^^^^^^^^
  File "/home/ubuntu/test-hrms/apps/frappe/frappe/utils/background_jobs.py", line 580, in get_job
    return Job.fetch(create_job_id(job_id), connection=get_redis_conn())
           ^^^^^^^^^^^^^^^^^^^^^^^^^^^^^^^^^^^^^^^^^^^^^^^^^^^^^^^^^^^^^
  File "/home/ubuntu/test-hrms/env/lib/python3.11/site-packages/rq/job.py", line 591, in fetch
    job.refresh()
  File "/home/ubuntu/test-hrms/env/lib/python3.11/site-packages/rq/job.py", line 989, in refresh
    data = self.connection.hgetall(self.key)
           ^^^^^^^^^^^^^^^^^^^^^^^^^^^^^^^^^
  File "/home/ubuntu/test-hrms/env/lib/python3.11/site-packages/redis/commands/core.py", line 4887, in hgetall
    return self.execute_command("HGETALL", name)
           ^^^^^^^^^^^^^^^^^^^^^^^^^^^^^^^^^^^^^
  File "/home/ubuntu/test-hrms/env/lib/python3.11/site-packages/redis/client.py", line 1266, in execute_command
    conn = self.connection or pool.get_connection(command_name, **options)
                              ^^^^^^^^^^^^^^^^^^^^^^^^^^^^^^^^^^^^^^^^^^^^
  File "/home/ubuntu/test-hrms/env/lib/python3.11/site-packages/redis/connection.py", line 1467, in get_connection
    connection.connect()
  File "/home/ubuntu/test-hrms/env/lib/python3.11/site-packages/redis/connection.py", line 705, in connect
    raise ConnectionError(self._error_message(e))
redis.exceptions.ConnectionError: Error 111 connecting to 127.0.0.1:11000. Connection refused.
2025-09-14 12:21:41,334 ERROR scheduler Exception in Enqueue Events for Site test-site.local
Traceback (most recent call last):
  File "/home/ubuntu/test-hrms/env/lib/python3.11/site-packages/redis/connection.py", line 699, in connect
    sock = self.retry.call_with_retry(
           ^^^^^^^^^^^^^^^^^^^^^^^^^^^
  File "/home/ubuntu/test-hrms/env/lib/python3.11/site-packages/redis/retry.py", line 46, in call_with_retry
    return do()
           ^^^^
  File "/home/ubuntu/test-hrms/env/lib/python3.11/site-packages/redis/connection.py", line 700, in <lambda>
    lambda: self._connect(), lambda error: self.disconnect(error)
            ^^^^^^^^^^^^^^^
  File "/home/ubuntu/test-hrms/env/lib/python3.11/site-packages/redis/connection.py", line 1002, in _connect
    raise err
  File "/home/ubuntu/test-hrms/env/lib/python3.11/site-packages/redis/connection.py", line 990, in _connect
    sock.connect(socket_address)
ConnectionRefusedError: [Errno 111] Connection refused

During handling of the above exception, another exception occurred:

Traceback (most recent call last):
  File "/home/ubuntu/test-hrms/apps/frappe/frappe/utils/scheduler.py", line 102, in enqueue_events_for_site
    enqueue_events(site=site)
  File "/home/ubuntu/test-hrms/apps/frappe/frappe/utils/scheduler.py", line 122, in enqueue_events
    if job_type.enqueue():
       ^^^^^^^^^^^^^^^^^^
  File "/home/ubuntu/test-hrms/apps/frappe/frappe/core/doctype/scheduled_job_type/scheduled_job_type.py", line 74, in enqueue
    if not self.is_job_in_queue():
           ^^^^^^^^^^^^^^^^^^^^^^
  File "/home/ubuntu/test-hrms/apps/frappe/frappe/core/doctype/scheduled_job_type/scheduled_job_type.py", line 95, in is_job_in_queue
    return is_job_enqueued(self.rq_job_id)
           ^^^^^^^^^^^^^^^^^^^^^^^^^^^^^^^
  File "/home/ubuntu/test-hrms/apps/frappe/frappe/utils/background_jobs.py", line 568, in is_job_enqueued
    return get_job_status(job_id) in (JobStatus.QUEUED, JobStatus.STARTED)
           ^^^^^^^^^^^^^^^^^^^^^^
  File "/home/ubuntu/test-hrms/apps/frappe/frappe/utils/background_jobs.py", line 573, in get_job_status
    job = get_job(job_id)
          ^^^^^^^^^^^^^^^
  File "/home/ubuntu/test-hrms/apps/frappe/frappe/utils/background_jobs.py", line 580, in get_job
    return Job.fetch(create_job_id(job_id), connection=get_redis_conn())
           ^^^^^^^^^^^^^^^^^^^^^^^^^^^^^^^^^^^^^^^^^^^^^^^^^^^^^^^^^^^^^
  File "/home/ubuntu/test-hrms/env/lib/python3.11/site-packages/rq/job.py", line 591, in fetch
    job.refresh()
  File "/home/ubuntu/test-hrms/env/lib/python3.11/site-packages/rq/job.py", line 989, in refresh
    data = self.connection.hgetall(self.key)
           ^^^^^^^^^^^^^^^^^^^^^^^^^^^^^^^^^
  File "/home/ubuntu/test-hrms/env/lib/python3.11/site-packages/redis/commands/core.py", line 4887, in hgetall
    return self.execute_command("HGETALL", name)
           ^^^^^^^^^^^^^^^^^^^^^^^^^^^^^^^^^^^^^
  File "/home/ubuntu/test-hrms/env/lib/python3.11/site-packages/redis/client.py", line 1266, in execute_command
    conn = self.connection or pool.get_connection(command_name, **options)
                              ^^^^^^^^^^^^^^^^^^^^^^^^^^^^^^^^^^^^^^^^^^^^
  File "/home/ubuntu/test-hrms/env/lib/python3.11/site-packages/redis/connection.py", line 1457, in get_connection
    connection.connect()
  File "/home/ubuntu/test-hrms/env/lib/python3.11/site-packages/redis/connection.py", line 705, in connect
    raise ConnectionError(self._error_message(e))
redis.exceptions.ConnectionError: Error 111 connecting to 127.0.0.1:11000. Connection refused.
2025-09-14 12:22:41,415 ERROR scheduler Exception in Enqueue Events for Site test-site.local
Traceback (most recent call last):
  File "/home/ubuntu/test-hrms/env/lib/python3.11/site-packages/redis/connection.py", line 699, in connect
    sock = self.retry.call_with_retry(
           ^^^^^^^^^^^^^^^^^^^^^^^^^^^
  File "/home/ubuntu/test-hrms/env/lib/python3.11/site-packages/redis/retry.py", line 46, in call_with_retry
    return do()
           ^^^^
  File "/home/ubuntu/test-hrms/env/lib/python3.11/site-packages/redis/connection.py", line 700, in <lambda>
    lambda: self._connect(), lambda error: self.disconnect(error)
            ^^^^^^^^^^^^^^^
  File "/home/ubuntu/test-hrms/env/lib/python3.11/site-packages/redis/connection.py", line 1002, in _connect
    raise err
  File "/home/ubuntu/test-hrms/env/lib/python3.11/site-packages/redis/connection.py", line 990, in _connect
    sock.connect(socket_address)
ConnectionRefusedError: [Errno 111] Connection refused

During handling of the above exception, another exception occurred:

Traceback (most recent call last):
  File "/home/ubuntu/test-hrms/apps/frappe/frappe/utils/scheduler.py", line 102, in enqueue_events_for_site
    enqueue_events(site=site)
  File "/home/ubuntu/test-hrms/apps/frappe/frappe/utils/scheduler.py", line 122, in enqueue_events
    if job_type.enqueue():
       ^^^^^^^^^^^^^^^^^^
  File "/home/ubuntu/test-hrms/apps/frappe/frappe/core/doctype/scheduled_job_type/scheduled_job_type.py", line 74, in enqueue
    if not self.is_job_in_queue():
           ^^^^^^^^^^^^^^^^^^^^^^
  File "/home/ubuntu/test-hrms/apps/frappe/frappe/core/doctype/scheduled_job_type/scheduled_job_type.py", line 95, in is_job_in_queue
    return is_job_enqueued(self.rq_job_id)
           ^^^^^^^^^^^^^^^^^^^^^^^^^^^^^^^
  File "/home/ubuntu/test-hrms/apps/frappe/frappe/utils/background_jobs.py", line 568, in is_job_enqueued
    return get_job_status(job_id) in (JobStatus.QUEUED, JobStatus.STARTED)
           ^^^^^^^^^^^^^^^^^^^^^^
  File "/home/ubuntu/test-hrms/apps/frappe/frappe/utils/background_jobs.py", line 573, in get_job_status
    job = get_job(job_id)
          ^^^^^^^^^^^^^^^
  File "/home/ubuntu/test-hrms/apps/frappe/frappe/utils/background_jobs.py", line 580, in get_job
    return Job.fetch(create_job_id(job_id), connection=get_redis_conn())
           ^^^^^^^^^^^^^^^^^^^^^^^^^^^^^^^^^^^^^^^^^^^^^^^^^^^^^^^^^^^^^
  File "/home/ubuntu/test-hrms/env/lib/python3.11/site-packages/rq/job.py", line 591, in fetch
    job.refresh()
  File "/home/ubuntu/test-hrms/env/lib/python3.11/site-packages/rq/job.py", line 989, in refresh
    data = self.connection.hgetall(self.key)
           ^^^^^^^^^^^^^^^^^^^^^^^^^^^^^^^^^
  File "/home/ubuntu/test-hrms/env/lib/python3.11/site-packages/redis/commands/core.py", line 4887, in hgetall
    return self.execute_command("HGETALL", name)
           ^^^^^^^^^^^^^^^^^^^^^^^^^^^^^^^^^^^^^
  File "/home/ubuntu/test-hrms/env/lib/python3.11/site-packages/redis/client.py", line 1266, in execute_command
    conn = self.connection or pool.get_connection(command_name, **options)
                              ^^^^^^^^^^^^^^^^^^^^^^^^^^^^^^^^^^^^^^^^^^^^
  File "/home/ubuntu/test-hrms/env/lib/python3.11/site-packages/redis/connection.py", line 1457, in get_connection
    connection.connect()
  File "/home/ubuntu/test-hrms/env/lib/python3.11/site-packages/redis/connection.py", line 705, in connect
    raise ConnectionError(self._error_message(e))
redis.exceptions.ConnectionError: Error 111 connecting to 127.0.0.1:11000. Connection refused.
2025-09-14 12:23:41,635 ERROR scheduler Exception in Enqueue Events for Site test-site.local
Traceback (most recent call last):
  File "/home/ubuntu/test-hrms/env/lib/python3.11/site-packages/redis/connection.py", line 699, in connect
    sock = self.retry.call_with_retry(
           ^^^^^^^^^^^^^^^^^^^^^^^^^^^
  File "/home/ubuntu/test-hrms/env/lib/python3.11/site-packages/redis/retry.py", line 46, in call_with_retry
    return do()
           ^^^^
  File "/home/ubuntu/test-hrms/env/lib/python3.11/site-packages/redis/connection.py", line 700, in <lambda>
    lambda: self._connect(), lambda error: self.disconnect(error)
            ^^^^^^^^^^^^^^^
  File "/home/ubuntu/test-hrms/env/lib/python3.11/site-packages/redis/connection.py", line 1002, in _connect
    raise err
  File "/home/ubuntu/test-hrms/env/lib/python3.11/site-packages/redis/connection.py", line 990, in _connect
    sock.connect(socket_address)
ConnectionRefusedError: [Errno 111] Connection refused

During handling of the above exception, another exception occurred:

Traceback (most recent call last):
  File "/home/ubuntu/test-hrms/apps/frappe/frappe/utils/scheduler.py", line 102, in enqueue_events_for_site
    enqueue_events(site=site)
  File "/home/ubuntu/test-hrms/apps/frappe/frappe/utils/scheduler.py", line 122, in enqueue_events
    if job_type.enqueue():
       ^^^^^^^^^^^^^^^^^^
  File "/home/ubuntu/test-hrms/apps/frappe/frappe/core/doctype/scheduled_job_type/scheduled_job_type.py", line 74, in enqueue
    if not self.is_job_in_queue():
           ^^^^^^^^^^^^^^^^^^^^^^
  File "/home/ubuntu/test-hrms/apps/frappe/frappe/core/doctype/scheduled_job_type/scheduled_job_type.py", line 95, in is_job_in_queue
    return is_job_enqueued(self.rq_job_id)
           ^^^^^^^^^^^^^^^^^^^^^^^^^^^^^^^
  File "/home/ubuntu/test-hrms/apps/frappe/frappe/utils/background_jobs.py", line 568, in is_job_enqueued
    return get_job_status(job_id) in (JobStatus.QUEUED, JobStatus.STARTED)
           ^^^^^^^^^^^^^^^^^^^^^^
  File "/home/ubuntu/test-hrms/apps/frappe/frappe/utils/background_jobs.py", line 573, in get_job_status
    job = get_job(job_id)
          ^^^^^^^^^^^^^^^
  File "/home/ubuntu/test-hrms/apps/frappe/frappe/utils/background_jobs.py", line 580, in get_job
    return Job.fetch(create_job_id(job_id), connection=get_redis_conn())
           ^^^^^^^^^^^^^^^^^^^^^^^^^^^^^^^^^^^^^^^^^^^^^^^^^^^^^^^^^^^^^
  File "/home/ubuntu/test-hrms/env/lib/python3.11/site-packages/rq/job.py", line 591, in fetch
    job.refresh()
  File "/home/ubuntu/test-hrms/env/lib/python3.11/site-packages/rq/job.py", line 989, in refresh
    data = self.connection.hgetall(self.key)
           ^^^^^^^^^^^^^^^^^^^^^^^^^^^^^^^^^
  File "/home/ubuntu/test-hrms/env/lib/python3.11/site-packages/redis/commands/core.py", line 4887, in hgetall
    return self.execute_command("HGETALL", name)
           ^^^^^^^^^^^^^^^^^^^^^^^^^^^^^^^^^^^^^
  File "/home/ubuntu/test-hrms/env/lib/python3.11/site-packages/redis/client.py", line 1266, in execute_command
    conn = self.connection or pool.get_connection(command_name, **options)
                              ^^^^^^^^^^^^^^^^^^^^^^^^^^^^^^^^^^^^^^^^^^^^
  File "/home/ubuntu/test-hrms/env/lib/python3.11/site-packages/redis/connection.py", line 1457, in get_connection
    connection.connect()
  File "/home/ubuntu/test-hrms/env/lib/python3.11/site-packages/redis/connection.py", line 705, in connect
    raise ConnectionError(self._error_message(e))
redis.exceptions.ConnectionError: Error 111 connecting to 127.0.0.1:11000. Connection refused.
2025-09-14 12:24:41,762 ERROR scheduler Exception in Enqueue Events for Site test-site.local
Traceback (most recent call last):
  File "/home/ubuntu/test-hrms/env/lib/python3.11/site-packages/redis/connection.py", line 699, in connect
    sock = self.retry.call_with_retry(
           ^^^^^^^^^^^^^^^^^^^^^^^^^^^
  File "/home/ubuntu/test-hrms/env/lib/python3.11/site-packages/redis/retry.py", line 46, in call_with_retry
    return do()
           ^^^^
  File "/home/ubuntu/test-hrms/env/lib/python3.11/site-packages/redis/connection.py", line 700, in <lambda>
    lambda: self._connect(), lambda error: self.disconnect(error)
            ^^^^^^^^^^^^^^^
  File "/home/ubuntu/test-hrms/env/lib/python3.11/site-packages/redis/connection.py", line 1002, in _connect
    raise err
  File "/home/ubuntu/test-hrms/env/lib/python3.11/site-packages/redis/connection.py", line 990, in _connect
    sock.connect(socket_address)
ConnectionRefusedError: [Errno 111] Connection refused

During handling of the above exception, another exception occurred:

Traceback (most recent call last):
  File "/home/ubuntu/test-hrms/apps/frappe/frappe/utils/scheduler.py", line 102, in enqueue_events_for_site
    enqueue_events(site=site)
  File "/home/ubuntu/test-hrms/apps/frappe/frappe/utils/scheduler.py", line 122, in enqueue_events
    if job_type.enqueue():
       ^^^^^^^^^^^^^^^^^^
  File "/home/ubuntu/test-hrms/apps/frappe/frappe/core/doctype/scheduled_job_type/scheduled_job_type.py", line 74, in enqueue
    if not self.is_job_in_queue():
           ^^^^^^^^^^^^^^^^^^^^^^
  File "/home/ubuntu/test-hrms/apps/frappe/frappe/core/doctype/scheduled_job_type/scheduled_job_type.py", line 95, in is_job_in_queue
    return is_job_enqueued(self.rq_job_id)
           ^^^^^^^^^^^^^^^^^^^^^^^^^^^^^^^
  File "/home/ubuntu/test-hrms/apps/frappe/frappe/utils/background_jobs.py", line 568, in is_job_enqueued
    return get_job_status(job_id) in (JobStatus.QUEUED, JobStatus.STARTED)
           ^^^^^^^^^^^^^^^^^^^^^^
  File "/home/ubuntu/test-hrms/apps/frappe/frappe/utils/background_jobs.py", line 573, in get_job_status
    job = get_job(job_id)
          ^^^^^^^^^^^^^^^
  File "/home/ubuntu/test-hrms/apps/frappe/frappe/utils/background_jobs.py", line 580, in get_job
    return Job.fetch(create_job_id(job_id), connection=get_redis_conn())
           ^^^^^^^^^^^^^^^^^^^^^^^^^^^^^^^^^^^^^^^^^^^^^^^^^^^^^^^^^^^^^
  File "/home/ubuntu/test-hrms/env/lib/python3.11/site-packages/rq/job.py", line 591, in fetch
    job.refresh()
  File "/home/ubuntu/test-hrms/env/lib/python3.11/site-packages/rq/job.py", line 989, in refresh
    data = self.connection.hgetall(self.key)
           ^^^^^^^^^^^^^^^^^^^^^^^^^^^^^^^^^
  File "/home/ubuntu/test-hrms/env/lib/python3.11/site-packages/redis/commands/core.py", line 4887, in hgetall
    return self.execute_command("HGETALL", name)
           ^^^^^^^^^^^^^^^^^^^^^^^^^^^^^^^^^^^^^
  File "/home/ubuntu/test-hrms/env/lib/python3.11/site-packages/redis/client.py", line 1266, in execute_command
    conn = self.connection or pool.get_connection(command_name, **options)
                              ^^^^^^^^^^^^^^^^^^^^^^^^^^^^^^^^^^^^^^^^^^^^
  File "/home/ubuntu/test-hrms/env/lib/python3.11/site-packages/redis/connection.py", line 1457, in get_connection
    connection.connect()
  File "/home/ubuntu/test-hrms/env/lib/python3.11/site-packages/redis/connection.py", line 705, in connect
    raise ConnectionError(self._error_message(e))
redis.exceptions.ConnectionError: Error 111 connecting to 127.0.0.1:11000. Connection refused.
2025-09-14 12:25:41,883 ERROR scheduler Exception in Enqueue Events for Site test-site.local
Traceback (most recent call last):
  File "/home/ubuntu/test-hrms/env/lib/python3.11/site-packages/redis/connection.py", line 699, in connect
    sock = self.retry.call_with_retry(
           ^^^^^^^^^^^^^^^^^^^^^^^^^^^
  File "/home/ubuntu/test-hrms/env/lib/python3.11/site-packages/redis/retry.py", line 46, in call_with_retry
    return do()
           ^^^^
  File "/home/ubuntu/test-hrms/env/lib/python3.11/site-packages/redis/connection.py", line 700, in <lambda>
    lambda: self._connect(), lambda error: self.disconnect(error)
            ^^^^^^^^^^^^^^^
  File "/home/ubuntu/test-hrms/env/lib/python3.11/site-packages/redis/connection.py", line 1002, in _connect
    raise err
  File "/home/ubuntu/test-hrms/env/lib/python3.11/site-packages/redis/connection.py", line 990, in _connect
    sock.connect(socket_address)
ConnectionRefusedError: [Errno 111] Connection refused

During handling of the above exception, another exception occurred:

Traceback (most recent call last):
  File "/home/ubuntu/test-hrms/apps/frappe/frappe/utils/scheduler.py", line 102, in enqueue_events_for_site
    enqueue_events(site=site)
  File "/home/ubuntu/test-hrms/apps/frappe/frappe/utils/scheduler.py", line 122, in enqueue_events
    if job_type.enqueue():
       ^^^^^^^^^^^^^^^^^^
  File "/home/ubuntu/test-hrms/apps/frappe/frappe/core/doctype/scheduled_job_type/scheduled_job_type.py", line 74, in enqueue
    if not self.is_job_in_queue():
           ^^^^^^^^^^^^^^^^^^^^^^
  File "/home/ubuntu/test-hrms/apps/frappe/frappe/core/doctype/scheduled_job_type/scheduled_job_type.py", line 95, in is_job_in_queue
    return is_job_enqueued(self.rq_job_id)
           ^^^^^^^^^^^^^^^^^^^^^^^^^^^^^^^
  File "/home/ubuntu/test-hrms/apps/frappe/frappe/utils/background_jobs.py", line 568, in is_job_enqueued
    return get_job_status(job_id) in (JobStatus.QUEUED, JobStatus.STARTED)
           ^^^^^^^^^^^^^^^^^^^^^^
  File "/home/ubuntu/test-hrms/apps/frappe/frappe/utils/background_jobs.py", line 573, in get_job_status
    job = get_job(job_id)
          ^^^^^^^^^^^^^^^
  File "/home/ubuntu/test-hrms/apps/frappe/frappe/utils/background_jobs.py", line 580, in get_job
    return Job.fetch(create_job_id(job_id), connection=get_redis_conn())
           ^^^^^^^^^^^^^^^^^^^^^^^^^^^^^^^^^^^^^^^^^^^^^^^^^^^^^^^^^^^^^
  File "/home/ubuntu/test-hrms/env/lib/python3.11/site-packages/rq/job.py", line 591, in fetch
    job.refresh()
  File "/home/ubuntu/test-hrms/env/lib/python3.11/site-packages/rq/job.py", line 989, in refresh
    data = self.connection.hgetall(self.key)
           ^^^^^^^^^^^^^^^^^^^^^^^^^^^^^^^^^
  File "/home/ubuntu/test-hrms/env/lib/python3.11/site-packages/redis/commands/core.py", line 4887, in hgetall
    return self.execute_command("HGETALL", name)
           ^^^^^^^^^^^^^^^^^^^^^^^^^^^^^^^^^^^^^
  File "/home/ubuntu/test-hrms/env/lib/python3.11/site-packages/redis/client.py", line 1266, in execute_command
    conn = self.connection or pool.get_connection(command_name, **options)
                              ^^^^^^^^^^^^^^^^^^^^^^^^^^^^^^^^^^^^^^^^^^^^
  File "/home/ubuntu/test-hrms/env/lib/python3.11/site-packages/redis/connection.py", line 1457, in get_connection
    connection.connect()
  File "/home/ubuntu/test-hrms/env/lib/python3.11/site-packages/redis/connection.py", line 705, in connect
    raise ConnectionError(self._error_message(e))
redis.exceptions.ConnectionError: Error 111 connecting to 127.0.0.1:11000. Connection refused.
2025-09-14 12:26:41,995 ERROR scheduler Exception in Enqueue Events for Site test-site.local
Traceback (most recent call last):
  File "/home/ubuntu/test-hrms/env/lib/python3.11/site-packages/redis/connection.py", line 699, in connect
    sock = self.retry.call_with_retry(
           ^^^^^^^^^^^^^^^^^^^^^^^^^^^
  File "/home/ubuntu/test-hrms/env/lib/python3.11/site-packages/redis/retry.py", line 46, in call_with_retry
    return do()
           ^^^^
  File "/home/ubuntu/test-hrms/env/lib/python3.11/site-packages/redis/connection.py", line 700, in <lambda>
    lambda: self._connect(), lambda error: self.disconnect(error)
            ^^^^^^^^^^^^^^^
  File "/home/ubuntu/test-hrms/env/lib/python3.11/site-packages/redis/connection.py", line 1002, in _connect
    raise err
  File "/home/ubuntu/test-hrms/env/lib/python3.11/site-packages/redis/connection.py", line 990, in _connect
    sock.connect(socket_address)
ConnectionRefusedError: [Errno 111] Connection refused

During handling of the above exception, another exception occurred:

Traceback (most recent call last):
  File "/home/ubuntu/test-hrms/apps/frappe/frappe/utils/scheduler.py", line 102, in enqueue_events_for_site
    enqueue_events(site=site)
  File "/home/ubuntu/test-hrms/apps/frappe/frappe/utils/scheduler.py", line 122, in enqueue_events
    if job_type.enqueue():
       ^^^^^^^^^^^^^^^^^^
  File "/home/ubuntu/test-hrms/apps/frappe/frappe/core/doctype/scheduled_job_type/scheduled_job_type.py", line 74, in enqueue
    if not self.is_job_in_queue():
           ^^^^^^^^^^^^^^^^^^^^^^
  File "/home/ubuntu/test-hrms/apps/frappe/frappe/core/doctype/scheduled_job_type/scheduled_job_type.py", line 95, in is_job_in_queue
    return is_job_enqueued(self.rq_job_id)
           ^^^^^^^^^^^^^^^^^^^^^^^^^^^^^^^
  File "/home/ubuntu/test-hrms/apps/frappe/frappe/utils/background_jobs.py", line 568, in is_job_enqueued
    return get_job_status(job_id) in (JobStatus.QUEUED, JobStatus.STARTED)
           ^^^^^^^^^^^^^^^^^^^^^^
  File "/home/ubuntu/test-hrms/apps/frappe/frappe/utils/background_jobs.py", line 573, in get_job_status
    job = get_job(job_id)
          ^^^^^^^^^^^^^^^
  File "/home/ubuntu/test-hrms/apps/frappe/frappe/utils/background_jobs.py", line 580, in get_job
    return Job.fetch(create_job_id(job_id), connection=get_redis_conn())
           ^^^^^^^^^^^^^^^^^^^^^^^^^^^^^^^^^^^^^^^^^^^^^^^^^^^^^^^^^^^^^
  File "/home/ubuntu/test-hrms/env/lib/python3.11/site-packages/rq/job.py", line 591, in fetch
    job.refresh()
  File "/home/ubuntu/test-hrms/env/lib/python3.11/site-packages/rq/job.py", line 989, in refresh
    data = self.connection.hgetall(self.key)
           ^^^^^^^^^^^^^^^^^^^^^^^^^^^^^^^^^
  File "/home/ubuntu/test-hrms/env/lib/python3.11/site-packages/redis/commands/core.py", line 4887, in hgetall
    return self.execute_command("HGETALL", name)
           ^^^^^^^^^^^^^^^^^^^^^^^^^^^^^^^^^^^^^
  File "/home/ubuntu/test-hrms/env/lib/python3.11/site-packages/redis/client.py", line 1266, in execute_command
    conn = self.connection or pool.get_connection(command_name, **options)
                              ^^^^^^^^^^^^^^^^^^^^^^^^^^^^^^^^^^^^^^^^^^^^
  File "/home/ubuntu/test-hrms/env/lib/python3.11/site-packages/redis/connection.py", line 1457, in get_connection
    connection.connect()
  File "/home/ubuntu/test-hrms/env/lib/python3.11/site-packages/redis/connection.py", line 705, in connect
    raise ConnectionError(self._error_message(e))
redis.exceptions.ConnectionError: Error 111 connecting to 127.0.0.1:11000. Connection refused.
2025-09-14 12:27:42,087 ERROR scheduler Exception in Enqueue Events for Site test-site.local
Traceback (most recent call last):
  File "/home/ubuntu/test-hrms/env/lib/python3.11/site-packages/redis/connection.py", line 699, in connect
    sock = self.retry.call_with_retry(
           ^^^^^^^^^^^^^^^^^^^^^^^^^^^
  File "/home/ubuntu/test-hrms/env/lib/python3.11/site-packages/redis/retry.py", line 46, in call_with_retry
    return do()
           ^^^^
  File "/home/ubuntu/test-hrms/env/lib/python3.11/site-packages/redis/connection.py", line 700, in <lambda>
    lambda: self._connect(), lambda error: self.disconnect(error)
            ^^^^^^^^^^^^^^^
  File "/home/ubuntu/test-hrms/env/lib/python3.11/site-packages/redis/connection.py", line 1002, in _connect
    raise err
  File "/home/ubuntu/test-hrms/env/lib/python3.11/site-packages/redis/connection.py", line 990, in _connect
    sock.connect(socket_address)
ConnectionRefusedError: [Errno 111] Connection refused

During handling of the above exception, another exception occurred:

Traceback (most recent call last):
  File "/home/ubuntu/test-hrms/apps/frappe/frappe/utils/scheduler.py", line 102, in enqueue_events_for_site
    enqueue_events(site=site)
  File "/home/ubuntu/test-hrms/apps/frappe/frappe/utils/scheduler.py", line 122, in enqueue_events
    if job_type.enqueue():
       ^^^^^^^^^^^^^^^^^^
  File "/home/ubuntu/test-hrms/apps/frappe/frappe/core/doctype/scheduled_job_type/scheduled_job_type.py", line 74, in enqueue
    if not self.is_job_in_queue():
           ^^^^^^^^^^^^^^^^^^^^^^
  File "/home/ubuntu/test-hrms/apps/frappe/frappe/core/doctype/scheduled_job_type/scheduled_job_type.py", line 95, in is_job_in_queue
    return is_job_enqueued(self.rq_job_id)
           ^^^^^^^^^^^^^^^^^^^^^^^^^^^^^^^
  File "/home/ubuntu/test-hrms/apps/frappe/frappe/utils/background_jobs.py", line 568, in is_job_enqueued
    return get_job_status(job_id) in (JobStatus.QUEUED, JobStatus.STARTED)
           ^^^^^^^^^^^^^^^^^^^^^^
  File "/home/ubuntu/test-hrms/apps/frappe/frappe/utils/background_jobs.py", line 573, in get_job_status
    job = get_job(job_id)
          ^^^^^^^^^^^^^^^
  File "/home/ubuntu/test-hrms/apps/frappe/frappe/utils/background_jobs.py", line 580, in get_job
    return Job.fetch(create_job_id(job_id), connection=get_redis_conn())
           ^^^^^^^^^^^^^^^^^^^^^^^^^^^^^^^^^^^^^^^^^^^^^^^^^^^^^^^^^^^^^
  File "/home/ubuntu/test-hrms/env/lib/python3.11/site-packages/rq/job.py", line 591, in fetch
    job.refresh()
  File "/home/ubuntu/test-hrms/env/lib/python3.11/site-packages/rq/job.py", line 989, in refresh
    data = self.connection.hgetall(self.key)
           ^^^^^^^^^^^^^^^^^^^^^^^^^^^^^^^^^
  File "/home/ubuntu/test-hrms/env/lib/python3.11/site-packages/redis/commands/core.py", line 4887, in hgetall
    return self.execute_command("HGETALL", name)
           ^^^^^^^^^^^^^^^^^^^^^^^^^^^^^^^^^^^^^
  File "/home/ubuntu/test-hrms/env/lib/python3.11/site-packages/redis/client.py", line 1266, in execute_command
    conn = self.connection or pool.get_connection(command_name, **options)
                              ^^^^^^^^^^^^^^^^^^^^^^^^^^^^^^^^^^^^^^^^^^^^
  File "/home/ubuntu/test-hrms/env/lib/python3.11/site-packages/redis/connection.py", line 1457, in get_connection
    connection.connect()
  File "/home/ubuntu/test-hrms/env/lib/python3.11/site-packages/redis/connection.py", line 705, in connect
    raise ConnectionError(self._error_message(e))
redis.exceptions.ConnectionError: Error 111 connecting to 127.0.0.1:11000. Connection refused.
2025-09-14 12:28:42,194 ERROR scheduler Exception in Enqueue Events for Site test-site.local
Traceback (most recent call last):
  File "/home/ubuntu/test-hrms/env/lib/python3.11/site-packages/redis/connection.py", line 699, in connect
    sock = self.retry.call_with_retry(
           ^^^^^^^^^^^^^^^^^^^^^^^^^^^
  File "/home/ubuntu/test-hrms/env/lib/python3.11/site-packages/redis/retry.py", line 46, in call_with_retry
    return do()
           ^^^^
  File "/home/ubuntu/test-hrms/env/lib/python3.11/site-packages/redis/connection.py", line 700, in <lambda>
    lambda: self._connect(), lambda error: self.disconnect(error)
            ^^^^^^^^^^^^^^^
  File "/home/ubuntu/test-hrms/env/lib/python3.11/site-packages/redis/connection.py", line 1002, in _connect
    raise err
  File "/home/ubuntu/test-hrms/env/lib/python3.11/site-packages/redis/connection.py", line 990, in _connect
    sock.connect(socket_address)
ConnectionRefusedError: [Errno 111] Connection refused

During handling of the above exception, another exception occurred:

Traceback (most recent call last):
  File "/home/ubuntu/test-hrms/apps/frappe/frappe/utils/scheduler.py", line 102, in enqueue_events_for_site
    enqueue_events(site=site)
  File "/home/ubuntu/test-hrms/apps/frappe/frappe/utils/scheduler.py", line 122, in enqueue_events
    if job_type.enqueue():
       ^^^^^^^^^^^^^^^^^^
  File "/home/ubuntu/test-hrms/apps/frappe/frappe/core/doctype/scheduled_job_type/scheduled_job_type.py", line 74, in enqueue
    if not self.is_job_in_queue():
           ^^^^^^^^^^^^^^^^^^^^^^
  File "/home/ubuntu/test-hrms/apps/frappe/frappe/core/doctype/scheduled_job_type/scheduled_job_type.py", line 95, in is_job_in_queue
    return is_job_enqueued(self.rq_job_id)
           ^^^^^^^^^^^^^^^^^^^^^^^^^^^^^^^
  File "/home/ubuntu/test-hrms/apps/frappe/frappe/utils/background_jobs.py", line 568, in is_job_enqueued
    return get_job_status(job_id) in (JobStatus.QUEUED, JobStatus.STARTED)
           ^^^^^^^^^^^^^^^^^^^^^^
  File "/home/ubuntu/test-hrms/apps/frappe/frappe/utils/background_jobs.py", line 573, in get_job_status
    job = get_job(job_id)
          ^^^^^^^^^^^^^^^
  File "/home/ubuntu/test-hrms/apps/frappe/frappe/utils/background_jobs.py", line 580, in get_job
    return Job.fetch(create_job_id(job_id), connection=get_redis_conn())
           ^^^^^^^^^^^^^^^^^^^^^^^^^^^^^^^^^^^^^^^^^^^^^^^^^^^^^^^^^^^^^
  File "/home/ubuntu/test-hrms/env/lib/python3.11/site-packages/rq/job.py", line 591, in fetch
    job.refresh()
  File "/home/ubuntu/test-hrms/env/lib/python3.11/site-packages/rq/job.py", line 989, in refresh
    data = self.connection.hgetall(self.key)
           ^^^^^^^^^^^^^^^^^^^^^^^^^^^^^^^^^
  File "/home/ubuntu/test-hrms/env/lib/python3.11/site-packages/redis/commands/core.py", line 4887, in hgetall
    return self.execute_command("HGETALL", name)
           ^^^^^^^^^^^^^^^^^^^^^^^^^^^^^^^^^^^^^
  File "/home/ubuntu/test-hrms/env/lib/python3.11/site-packages/redis/client.py", line 1266, in execute_command
    conn = self.connection or pool.get_connection(command_name, **options)
                              ^^^^^^^^^^^^^^^^^^^^^^^^^^^^^^^^^^^^^^^^^^^^
  File "/home/ubuntu/test-hrms/env/lib/python3.11/site-packages/redis/connection.py", line 1457, in get_connection
    connection.connect()
  File "/home/ubuntu/test-hrms/env/lib/python3.11/site-packages/redis/connection.py", line 705, in connect
    raise ConnectionError(self._error_message(e))
redis.exceptions.ConnectionError: Error 111 connecting to 127.0.0.1:11000. Connection refused.
2025-09-14 12:29:42,283 ERROR scheduler Exception in Enqueue Events for Site test-site.local
Traceback (most recent call last):
  File "/home/ubuntu/test-hrms/env/lib/python3.11/site-packages/redis/connection.py", line 699, in connect
    sock = self.retry.call_with_retry(
           ^^^^^^^^^^^^^^^^^^^^^^^^^^^
  File "/home/ubuntu/test-hrms/env/lib/python3.11/site-packages/redis/retry.py", line 46, in call_with_retry
    return do()
           ^^^^
  File "/home/ubuntu/test-hrms/env/lib/python3.11/site-packages/redis/connection.py", line 700, in <lambda>
    lambda: self._connect(), lambda error: self.disconnect(error)
            ^^^^^^^^^^^^^^^
  File "/home/ubuntu/test-hrms/env/lib/python3.11/site-packages/redis/connection.py", line 1002, in _connect
    raise err
  File "/home/ubuntu/test-hrms/env/lib/python3.11/site-packages/redis/connection.py", line 990, in _connect
    sock.connect(socket_address)
ConnectionRefusedError: [Errno 111] Connection refused

During handling of the above exception, another exception occurred:

Traceback (most recent call last):
  File "/home/ubuntu/test-hrms/apps/frappe/frappe/utils/scheduler.py", line 102, in enqueue_events_for_site
    enqueue_events(site=site)
  File "/home/ubuntu/test-hrms/apps/frappe/frappe/utils/scheduler.py", line 122, in enqueue_events
    if job_type.enqueue():
       ^^^^^^^^^^^^^^^^^^
  File "/home/ubuntu/test-hrms/apps/frappe/frappe/core/doctype/scheduled_job_type/scheduled_job_type.py", line 74, in enqueue
    if not self.is_job_in_queue():
           ^^^^^^^^^^^^^^^^^^^^^^
  File "/home/ubuntu/test-hrms/apps/frappe/frappe/core/doctype/scheduled_job_type/scheduled_job_type.py", line 95, in is_job_in_queue
    return is_job_enqueued(self.rq_job_id)
           ^^^^^^^^^^^^^^^^^^^^^^^^^^^^^^^
  File "/home/ubuntu/test-hrms/apps/frappe/frappe/utils/background_jobs.py", line 568, in is_job_enqueued
    return get_job_status(job_id) in (JobStatus.QUEUED, JobStatus.STARTED)
           ^^^^^^^^^^^^^^^^^^^^^^
  File "/home/ubuntu/test-hrms/apps/frappe/frappe/utils/background_jobs.py", line 573, in get_job_status
    job = get_job(job_id)
          ^^^^^^^^^^^^^^^
  File "/home/ubuntu/test-hrms/apps/frappe/frappe/utils/background_jobs.py", line 580, in get_job
    return Job.fetch(create_job_id(job_id), connection=get_redis_conn())
           ^^^^^^^^^^^^^^^^^^^^^^^^^^^^^^^^^^^^^^^^^^^^^^^^^^^^^^^^^^^^^
  File "/home/ubuntu/test-hrms/env/lib/python3.11/site-packages/rq/job.py", line 591, in fetch
    job.refresh()
  File "/home/ubuntu/test-hrms/env/lib/python3.11/site-packages/rq/job.py", line 989, in refresh
    data = self.connection.hgetall(self.key)
           ^^^^^^^^^^^^^^^^^^^^^^^^^^^^^^^^^
  File "/home/ubuntu/test-hrms/env/lib/python3.11/site-packages/redis/commands/core.py", line 4887, in hgetall
    return self.execute_command("HGETALL", name)
           ^^^^^^^^^^^^^^^^^^^^^^^^^^^^^^^^^^^^^
  File "/home/ubuntu/test-hrms/env/lib/python3.11/site-packages/redis/client.py", line 1266, in execute_command
    conn = self.connection or pool.get_connection(command_name, **options)
                              ^^^^^^^^^^^^^^^^^^^^^^^^^^^^^^^^^^^^^^^^^^^^
  File "/home/ubuntu/test-hrms/env/lib/python3.11/site-packages/redis/connection.py", line 1457, in get_connection
    connection.connect()
  File "/home/ubuntu/test-hrms/env/lib/python3.11/site-packages/redis/connection.py", line 705, in connect
    raise ConnectionError(self._error_message(e))
redis.exceptions.ConnectionError: Error 111 connecting to 127.0.0.1:11000. Connection refused.
2025-09-14 12:30:42,365 ERROR scheduler Exception in Enqueue Events for Site test-site.local
Traceback (most recent call last):
  File "/home/ubuntu/test-hrms/env/lib/python3.11/site-packages/redis/connection.py", line 699, in connect
    sock = self.retry.call_with_retry(
           ^^^^^^^^^^^^^^^^^^^^^^^^^^^
  File "/home/ubuntu/test-hrms/env/lib/python3.11/site-packages/redis/retry.py", line 46, in call_with_retry
    return do()
           ^^^^
  File "/home/ubuntu/test-hrms/env/lib/python3.11/site-packages/redis/connection.py", line 700, in <lambda>
    lambda: self._connect(), lambda error: self.disconnect(error)
            ^^^^^^^^^^^^^^^
  File "/home/ubuntu/test-hrms/env/lib/python3.11/site-packages/redis/connection.py", line 1002, in _connect
    raise err
  File "/home/ubuntu/test-hrms/env/lib/python3.11/site-packages/redis/connection.py", line 990, in _connect
    sock.connect(socket_address)
ConnectionRefusedError: [Errno 111] Connection refused

During handling of the above exception, another exception occurred:

Traceback (most recent call last):
  File "/home/ubuntu/test-hrms/apps/frappe/frappe/utils/scheduler.py", line 102, in enqueue_events_for_site
    enqueue_events(site=site)
  File "/home/ubuntu/test-hrms/apps/frappe/frappe/utils/scheduler.py", line 122, in enqueue_events
    if job_type.enqueue():
       ^^^^^^^^^^^^^^^^^^
  File "/home/ubuntu/test-hrms/apps/frappe/frappe/core/doctype/scheduled_job_type/scheduled_job_type.py", line 74, in enqueue
    if not self.is_job_in_queue():
           ^^^^^^^^^^^^^^^^^^^^^^
  File "/home/ubuntu/test-hrms/apps/frappe/frappe/core/doctype/scheduled_job_type/scheduled_job_type.py", line 95, in is_job_in_queue
    return is_job_enqueued(self.rq_job_id)
           ^^^^^^^^^^^^^^^^^^^^^^^^^^^^^^^
  File "/home/ubuntu/test-hrms/apps/frappe/frappe/utils/background_jobs.py", line 568, in is_job_enqueued
    return get_job_status(job_id) in (JobStatus.QUEUED, JobStatus.STARTED)
           ^^^^^^^^^^^^^^^^^^^^^^
  File "/home/ubuntu/test-hrms/apps/frappe/frappe/utils/background_jobs.py", line 573, in get_job_status
    job = get_job(job_id)
          ^^^^^^^^^^^^^^^
  File "/home/ubuntu/test-hrms/apps/frappe/frappe/utils/background_jobs.py", line 580, in get_job
    return Job.fetch(create_job_id(job_id), connection=get_redis_conn())
           ^^^^^^^^^^^^^^^^^^^^^^^^^^^^^^^^^^^^^^^^^^^^^^^^^^^^^^^^^^^^^
  File "/home/ubuntu/test-hrms/env/lib/python3.11/site-packages/rq/job.py", line 591, in fetch
    job.refresh()
  File "/home/ubuntu/test-hrms/env/lib/python3.11/site-packages/rq/job.py", line 989, in refresh
    data = self.connection.hgetall(self.key)
           ^^^^^^^^^^^^^^^^^^^^^^^^^^^^^^^^^
  File "/home/ubuntu/test-hrms/env/lib/python3.11/site-packages/redis/commands/core.py", line 4887, in hgetall
    return self.execute_command("HGETALL", name)
           ^^^^^^^^^^^^^^^^^^^^^^^^^^^^^^^^^^^^^
  File "/home/ubuntu/test-hrms/env/lib/python3.11/site-packages/redis/client.py", line 1266, in execute_command
    conn = self.connection or pool.get_connection(command_name, **options)
                              ^^^^^^^^^^^^^^^^^^^^^^^^^^^^^^^^^^^^^^^^^^^^
  File "/home/ubuntu/test-hrms/env/lib/python3.11/site-packages/redis/connection.py", line 1457, in get_connection
    connection.connect()
  File "/home/ubuntu/test-hrms/env/lib/python3.11/site-packages/redis/connection.py", line 705, in connect
    raise ConnectionError(self._error_message(e))
redis.exceptions.ConnectionError: Error 111 connecting to 127.0.0.1:11000. Connection refused.
2025-09-14 12:31:42,457 ERROR scheduler Exception in Enqueue Events for Site test-site.local
Traceback (most recent call last):
  File "/home/ubuntu/test-hrms/env/lib/python3.11/site-packages/redis/connection.py", line 699, in connect
    sock = self.retry.call_with_retry(
           ^^^^^^^^^^^^^^^^^^^^^^^^^^^
  File "/home/ubuntu/test-hrms/env/lib/python3.11/site-packages/redis/retry.py", line 46, in call_with_retry
    return do()
           ^^^^
  File "/home/ubuntu/test-hrms/env/lib/python3.11/site-packages/redis/connection.py", line 700, in <lambda>
    lambda: self._connect(), lambda error: self.disconnect(error)
            ^^^^^^^^^^^^^^^
  File "/home/ubuntu/test-hrms/env/lib/python3.11/site-packages/redis/connection.py", line 1002, in _connect
    raise err
  File "/home/ubuntu/test-hrms/env/lib/python3.11/site-packages/redis/connection.py", line 990, in _connect
    sock.connect(socket_address)
ConnectionRefusedError: [Errno 111] Connection refused

During handling of the above exception, another exception occurred:

Traceback (most recent call last):
  File "/home/ubuntu/test-hrms/apps/frappe/frappe/utils/scheduler.py", line 102, in enqueue_events_for_site
    enqueue_events(site=site)
  File "/home/ubuntu/test-hrms/apps/frappe/frappe/utils/scheduler.py", line 122, in enqueue_events
    if job_type.enqueue():
       ^^^^^^^^^^^^^^^^^^
  File "/home/ubuntu/test-hrms/apps/frappe/frappe/core/doctype/scheduled_job_type/scheduled_job_type.py", line 74, in enqueue
    if not self.is_job_in_queue():
           ^^^^^^^^^^^^^^^^^^^^^^
  File "/home/ubuntu/test-hrms/apps/frappe/frappe/core/doctype/scheduled_job_type/scheduled_job_type.py", line 95, in is_job_in_queue
    return is_job_enqueued(self.rq_job_id)
           ^^^^^^^^^^^^^^^^^^^^^^^^^^^^^^^
  File "/home/ubuntu/test-hrms/apps/frappe/frappe/utils/background_jobs.py", line 568, in is_job_enqueued
    return get_job_status(job_id) in (JobStatus.QUEUED, JobStatus.STARTED)
           ^^^^^^^^^^^^^^^^^^^^^^
  File "/home/ubuntu/test-hrms/apps/frappe/frappe/utils/background_jobs.py", line 573, in get_job_status
    job = get_job(job_id)
          ^^^^^^^^^^^^^^^
  File "/home/ubuntu/test-hrms/apps/frappe/frappe/utils/background_jobs.py", line 580, in get_job
    return Job.fetch(create_job_id(job_id), connection=get_redis_conn())
           ^^^^^^^^^^^^^^^^^^^^^^^^^^^^^^^^^^^^^^^^^^^^^^^^^^^^^^^^^^^^^
  File "/home/ubuntu/test-hrms/env/lib/python3.11/site-packages/rq/job.py", line 591, in fetch
    job.refresh()
  File "/home/ubuntu/test-hrms/env/lib/python3.11/site-packages/rq/job.py", line 989, in refresh
    data = self.connection.hgetall(self.key)
           ^^^^^^^^^^^^^^^^^^^^^^^^^^^^^^^^^
  File "/home/ubuntu/test-hrms/env/lib/python3.11/site-packages/redis/commands/core.py", line 4887, in hgetall
    return self.execute_command("HGETALL", name)
           ^^^^^^^^^^^^^^^^^^^^^^^^^^^^^^^^^^^^^
  File "/home/ubuntu/test-hrms/env/lib/python3.11/site-packages/redis/client.py", line 1266, in execute_command
    conn = self.connection or pool.get_connection(command_name, **options)
                              ^^^^^^^^^^^^^^^^^^^^^^^^^^^^^^^^^^^^^^^^^^^^
  File "/home/ubuntu/test-hrms/env/lib/python3.11/site-packages/redis/connection.py", line 1457, in get_connection
    connection.connect()
  File "/home/ubuntu/test-hrms/env/lib/python3.11/site-packages/redis/connection.py", line 705, in connect
    raise ConnectionError(self._error_message(e))
redis.exceptions.ConnectionError: Error 111 connecting to 127.0.0.1:11000. Connection refused.
2025-09-14 12:32:42,540 ERROR scheduler Exception in Enqueue Events for Site test-site.local
Traceback (most recent call last):
  File "/home/ubuntu/test-hrms/env/lib/python3.11/site-packages/redis/connection.py", line 699, in connect
    sock = self.retry.call_with_retry(
           ^^^^^^^^^^^^^^^^^^^^^^^^^^^
  File "/home/ubuntu/test-hrms/env/lib/python3.11/site-packages/redis/retry.py", line 46, in call_with_retry
    return do()
           ^^^^
  File "/home/ubuntu/test-hrms/env/lib/python3.11/site-packages/redis/connection.py", line 700, in <lambda>
    lambda: self._connect(), lambda error: self.disconnect(error)
            ^^^^^^^^^^^^^^^
  File "/home/ubuntu/test-hrms/env/lib/python3.11/site-packages/redis/connection.py", line 1002, in _connect
    raise err
  File "/home/ubuntu/test-hrms/env/lib/python3.11/site-packages/redis/connection.py", line 990, in _connect
    sock.connect(socket_address)
ConnectionRefusedError: [Errno 111] Connection refused

During handling of the above exception, another exception occurred:

Traceback (most recent call last):
  File "/home/ubuntu/test-hrms/apps/frappe/frappe/utils/scheduler.py", line 102, in enqueue_events_for_site
    enqueue_events(site=site)
  File "/home/ubuntu/test-hrms/apps/frappe/frappe/utils/scheduler.py", line 122, in enqueue_events
    if job_type.enqueue():
       ^^^^^^^^^^^^^^^^^^
  File "/home/ubuntu/test-hrms/apps/frappe/frappe/core/doctype/scheduled_job_type/scheduled_job_type.py", line 74, in enqueue
    if not self.is_job_in_queue():
           ^^^^^^^^^^^^^^^^^^^^^^
  File "/home/ubuntu/test-hrms/apps/frappe/frappe/core/doctype/scheduled_job_type/scheduled_job_type.py", line 95, in is_job_in_queue
    return is_job_enqueued(self.rq_job_id)
           ^^^^^^^^^^^^^^^^^^^^^^^^^^^^^^^
  File "/home/ubuntu/test-hrms/apps/frappe/frappe/utils/background_jobs.py", line 568, in is_job_enqueued
    return get_job_status(job_id) in (JobStatus.QUEUED, JobStatus.STARTED)
           ^^^^^^^^^^^^^^^^^^^^^^
  File "/home/ubuntu/test-hrms/apps/frappe/frappe/utils/background_jobs.py", line 573, in get_job_status
    job = get_job(job_id)
          ^^^^^^^^^^^^^^^
  File "/home/ubuntu/test-hrms/apps/frappe/frappe/utils/background_jobs.py", line 580, in get_job
    return Job.fetch(create_job_id(job_id), connection=get_redis_conn())
           ^^^^^^^^^^^^^^^^^^^^^^^^^^^^^^^^^^^^^^^^^^^^^^^^^^^^^^^^^^^^^
  File "/home/ubuntu/test-hrms/env/lib/python3.11/site-packages/rq/job.py", line 591, in fetch
    job.refresh()
  File "/home/ubuntu/test-hrms/env/lib/python3.11/site-packages/rq/job.py", line 989, in refresh
    data = self.connection.hgetall(self.key)
           ^^^^^^^^^^^^^^^^^^^^^^^^^^^^^^^^^
  File "/home/ubuntu/test-hrms/env/lib/python3.11/site-packages/redis/commands/core.py", line 4887, in hgetall
    return self.execute_command("HGETALL", name)
           ^^^^^^^^^^^^^^^^^^^^^^^^^^^^^^^^^^^^^
  File "/home/ubuntu/test-hrms/env/lib/python3.11/site-packages/redis/client.py", line 1266, in execute_command
    conn = self.connection or pool.get_connection(command_name, **options)
                              ^^^^^^^^^^^^^^^^^^^^^^^^^^^^^^^^^^^^^^^^^^^^
  File "/home/ubuntu/test-hrms/env/lib/python3.11/site-packages/redis/connection.py", line 1457, in get_connection
    connection.connect()
  File "/home/ubuntu/test-hrms/env/lib/python3.11/site-packages/redis/connection.py", line 705, in connect
    raise ConnectionError(self._error_message(e))
redis.exceptions.ConnectionError: Error 111 connecting to 127.0.0.1:11000. Connection refused.
2025-09-14 12:33:42,623 ERROR scheduler Exception in Enqueue Events for Site test-site.local
Traceback (most recent call last):
  File "/home/ubuntu/test-hrms/env/lib/python3.11/site-packages/redis/connection.py", line 699, in connect
    sock = self.retry.call_with_retry(
           ^^^^^^^^^^^^^^^^^^^^^^^^^^^
  File "/home/ubuntu/test-hrms/env/lib/python3.11/site-packages/redis/retry.py", line 46, in call_with_retry
    return do()
           ^^^^
  File "/home/ubuntu/test-hrms/env/lib/python3.11/site-packages/redis/connection.py", line 700, in <lambda>
    lambda: self._connect(), lambda error: self.disconnect(error)
            ^^^^^^^^^^^^^^^
  File "/home/ubuntu/test-hrms/env/lib/python3.11/site-packages/redis/connection.py", line 1002, in _connect
    raise err
  File "/home/ubuntu/test-hrms/env/lib/python3.11/site-packages/redis/connection.py", line 990, in _connect
    sock.connect(socket_address)
ConnectionRefusedError: [Errno 111] Connection refused

During handling of the above exception, another exception occurred:

Traceback (most recent call last):
  File "/home/ubuntu/test-hrms/apps/frappe/frappe/utils/scheduler.py", line 102, in enqueue_events_for_site
    enqueue_events(site=site)
  File "/home/ubuntu/test-hrms/apps/frappe/frappe/utils/scheduler.py", line 122, in enqueue_events
    if job_type.enqueue():
       ^^^^^^^^^^^^^^^^^^
  File "/home/ubuntu/test-hrms/apps/frappe/frappe/core/doctype/scheduled_job_type/scheduled_job_type.py", line 74, in enqueue
    if not self.is_job_in_queue():
           ^^^^^^^^^^^^^^^^^^^^^^
  File "/home/ubuntu/test-hrms/apps/frappe/frappe/core/doctype/scheduled_job_type/scheduled_job_type.py", line 95, in is_job_in_queue
    return is_job_enqueued(self.rq_job_id)
           ^^^^^^^^^^^^^^^^^^^^^^^^^^^^^^^
  File "/home/ubuntu/test-hrms/apps/frappe/frappe/utils/background_jobs.py", line 568, in is_job_enqueued
    return get_job_status(job_id) in (JobStatus.QUEUED, JobStatus.STARTED)
           ^^^^^^^^^^^^^^^^^^^^^^
  File "/home/ubuntu/test-hrms/apps/frappe/frappe/utils/background_jobs.py", line 573, in get_job_status
    job = get_job(job_id)
          ^^^^^^^^^^^^^^^
  File "/home/ubuntu/test-hrms/apps/frappe/frappe/utils/background_jobs.py", line 580, in get_job
    return Job.fetch(create_job_id(job_id), connection=get_redis_conn())
           ^^^^^^^^^^^^^^^^^^^^^^^^^^^^^^^^^^^^^^^^^^^^^^^^^^^^^^^^^^^^^
  File "/home/ubuntu/test-hrms/env/lib/python3.11/site-packages/rq/job.py", line 591, in fetch
    job.refresh()
  File "/home/ubuntu/test-hrms/env/lib/python3.11/site-packages/rq/job.py", line 989, in refresh
    data = self.connection.hgetall(self.key)
           ^^^^^^^^^^^^^^^^^^^^^^^^^^^^^^^^^
  File "/home/ubuntu/test-hrms/env/lib/python3.11/site-packages/redis/commands/core.py", line 4887, in hgetall
    return self.execute_command("HGETALL", name)
           ^^^^^^^^^^^^^^^^^^^^^^^^^^^^^^^^^^^^^
  File "/home/ubuntu/test-hrms/env/lib/python3.11/site-packages/redis/client.py", line 1266, in execute_command
    conn = self.connection or pool.get_connection(command_name, **options)
                              ^^^^^^^^^^^^^^^^^^^^^^^^^^^^^^^^^^^^^^^^^^^^
  File "/home/ubuntu/test-hrms/env/lib/python3.11/site-packages/redis/connection.py", line 1457, in get_connection
    connection.connect()
  File "/home/ubuntu/test-hrms/env/lib/python3.11/site-packages/redis/connection.py", line 705, in connect
    raise ConnectionError(self._error_message(e))
redis.exceptions.ConnectionError: Error 111 connecting to 127.0.0.1:11000. Connection refused.
2025-09-14 12:34:42,707 ERROR scheduler Exception in Enqueue Events for Site test-site.local
Traceback (most recent call last):
  File "/home/ubuntu/test-hrms/env/lib/python3.11/site-packages/redis/connection.py", line 699, in connect
    sock = self.retry.call_with_retry(
           ^^^^^^^^^^^^^^^^^^^^^^^^^^^
  File "/home/ubuntu/test-hrms/env/lib/python3.11/site-packages/redis/retry.py", line 46, in call_with_retry
    return do()
           ^^^^
  File "/home/ubuntu/test-hrms/env/lib/python3.11/site-packages/redis/connection.py", line 700, in <lambda>
    lambda: self._connect(), lambda error: self.disconnect(error)
            ^^^^^^^^^^^^^^^
  File "/home/ubuntu/test-hrms/env/lib/python3.11/site-packages/redis/connection.py", line 1002, in _connect
    raise err
  File "/home/ubuntu/test-hrms/env/lib/python3.11/site-packages/redis/connection.py", line 990, in _connect
    sock.connect(socket_address)
ConnectionRefusedError: [Errno 111] Connection refused

During handling of the above exception, another exception occurred:

Traceback (most recent call last):
  File "/home/ubuntu/test-hrms/apps/frappe/frappe/utils/scheduler.py", line 102, in enqueue_events_for_site
    enqueue_events(site=site)
  File "/home/ubuntu/test-hrms/apps/frappe/frappe/utils/scheduler.py", line 122, in enqueue_events
    if job_type.enqueue():
       ^^^^^^^^^^^^^^^^^^
  File "/home/ubuntu/test-hrms/apps/frappe/frappe/core/doctype/scheduled_job_type/scheduled_job_type.py", line 74, in enqueue
    if not self.is_job_in_queue():
           ^^^^^^^^^^^^^^^^^^^^^^
  File "/home/ubuntu/test-hrms/apps/frappe/frappe/core/doctype/scheduled_job_type/scheduled_job_type.py", line 95, in is_job_in_queue
    return is_job_enqueued(self.rq_job_id)
           ^^^^^^^^^^^^^^^^^^^^^^^^^^^^^^^
  File "/home/ubuntu/test-hrms/apps/frappe/frappe/utils/background_jobs.py", line 568, in is_job_enqueued
    return get_job_status(job_id) in (JobStatus.QUEUED, JobStatus.STARTED)
           ^^^^^^^^^^^^^^^^^^^^^^
  File "/home/ubuntu/test-hrms/apps/frappe/frappe/utils/background_jobs.py", line 573, in get_job_status
    job = get_job(job_id)
          ^^^^^^^^^^^^^^^
  File "/home/ubuntu/test-hrms/apps/frappe/frappe/utils/background_jobs.py", line 580, in get_job
    return Job.fetch(create_job_id(job_id), connection=get_redis_conn())
           ^^^^^^^^^^^^^^^^^^^^^^^^^^^^^^^^^^^^^^^^^^^^^^^^^^^^^^^^^^^^^
  File "/home/ubuntu/test-hrms/env/lib/python3.11/site-packages/rq/job.py", line 591, in fetch
    job.refresh()
  File "/home/ubuntu/test-hrms/env/lib/python3.11/site-packages/rq/job.py", line 989, in refresh
    data = self.connection.hgetall(self.key)
           ^^^^^^^^^^^^^^^^^^^^^^^^^^^^^^^^^
  File "/home/ubuntu/test-hrms/env/lib/python3.11/site-packages/redis/commands/core.py", line 4887, in hgetall
    return self.execute_command("HGETALL", name)
           ^^^^^^^^^^^^^^^^^^^^^^^^^^^^^^^^^^^^^
  File "/home/ubuntu/test-hrms/env/lib/python3.11/site-packages/redis/client.py", line 1266, in execute_command
    conn = self.connection or pool.get_connection(command_name, **options)
                              ^^^^^^^^^^^^^^^^^^^^^^^^^^^^^^^^^^^^^^^^^^^^
  File "/home/ubuntu/test-hrms/env/lib/python3.11/site-packages/redis/connection.py", line 1457, in get_connection
    connection.connect()
  File "/home/ubuntu/test-hrms/env/lib/python3.11/site-packages/redis/connection.py", line 705, in connect
    raise ConnectionError(self._error_message(e))
redis.exceptions.ConnectionError: Error 111 connecting to 127.0.0.1:11000. Connection refused.
2025-09-14 12:35:42,797 ERROR scheduler Exception in Enqueue Events for Site test-site.local
Traceback (most recent call last):
  File "/home/ubuntu/test-hrms/env/lib/python3.11/site-packages/redis/connection.py", line 699, in connect
    sock = self.retry.call_with_retry(
           ^^^^^^^^^^^^^^^^^^^^^^^^^^^
  File "/home/ubuntu/test-hrms/env/lib/python3.11/site-packages/redis/retry.py", line 46, in call_with_retry
    return do()
           ^^^^
  File "/home/ubuntu/test-hrms/env/lib/python3.11/site-packages/redis/connection.py", line 700, in <lambda>
    lambda: self._connect(), lambda error: self.disconnect(error)
            ^^^^^^^^^^^^^^^
  File "/home/ubuntu/test-hrms/env/lib/python3.11/site-packages/redis/connection.py", line 1002, in _connect
    raise err
  File "/home/ubuntu/test-hrms/env/lib/python3.11/site-packages/redis/connection.py", line 990, in _connect
    sock.connect(socket_address)
ConnectionRefusedError: [Errno 111] Connection refused

During handling of the above exception, another exception occurred:

Traceback (most recent call last):
  File "/home/ubuntu/test-hrms/apps/frappe/frappe/utils/scheduler.py", line 102, in enqueue_events_for_site
    enqueue_events(site=site)
  File "/home/ubuntu/test-hrms/apps/frappe/frappe/utils/scheduler.py", line 122, in enqueue_events
    if job_type.enqueue():
       ^^^^^^^^^^^^^^^^^^
  File "/home/ubuntu/test-hrms/apps/frappe/frappe/core/doctype/scheduled_job_type/scheduled_job_type.py", line 74, in enqueue
    if not self.is_job_in_queue():
           ^^^^^^^^^^^^^^^^^^^^^^
  File "/home/ubuntu/test-hrms/apps/frappe/frappe/core/doctype/scheduled_job_type/scheduled_job_type.py", line 95, in is_job_in_queue
    return is_job_enqueued(self.rq_job_id)
           ^^^^^^^^^^^^^^^^^^^^^^^^^^^^^^^
  File "/home/ubuntu/test-hrms/apps/frappe/frappe/utils/background_jobs.py", line 568, in is_job_enqueued
    return get_job_status(job_id) in (JobStatus.QUEUED, JobStatus.STARTED)
           ^^^^^^^^^^^^^^^^^^^^^^
  File "/home/ubuntu/test-hrms/apps/frappe/frappe/utils/background_jobs.py", line 573, in get_job_status
    job = get_job(job_id)
          ^^^^^^^^^^^^^^^
  File "/home/ubuntu/test-hrms/apps/frappe/frappe/utils/background_jobs.py", line 580, in get_job
    return Job.fetch(create_job_id(job_id), connection=get_redis_conn())
           ^^^^^^^^^^^^^^^^^^^^^^^^^^^^^^^^^^^^^^^^^^^^^^^^^^^^^^^^^^^^^
  File "/home/ubuntu/test-hrms/env/lib/python3.11/site-packages/rq/job.py", line 591, in fetch
    job.refresh()
  File "/home/ubuntu/test-hrms/env/lib/python3.11/site-packages/rq/job.py", line 989, in refresh
    data = self.connection.hgetall(self.key)
           ^^^^^^^^^^^^^^^^^^^^^^^^^^^^^^^^^
  File "/home/ubuntu/test-hrms/env/lib/python3.11/site-packages/redis/commands/core.py", line 4887, in hgetall
    return self.execute_command("HGETALL", name)
           ^^^^^^^^^^^^^^^^^^^^^^^^^^^^^^^^^^^^^
  File "/home/ubuntu/test-hrms/env/lib/python3.11/site-packages/redis/client.py", line 1266, in execute_command
    conn = self.connection or pool.get_connection(command_name, **options)
                              ^^^^^^^^^^^^^^^^^^^^^^^^^^^^^^^^^^^^^^^^^^^^
  File "/home/ubuntu/test-hrms/env/lib/python3.11/site-packages/redis/connection.py", line 1457, in get_connection
    connection.connect()
  File "/home/ubuntu/test-hrms/env/lib/python3.11/site-packages/redis/connection.py", line 705, in connect
    raise ConnectionError(self._error_message(e))
redis.exceptions.ConnectionError: Error 111 connecting to 127.0.0.1:11000. Connection refused.
2025-09-14 12:36:42,894 ERROR scheduler Exception in Enqueue Events for Site test-site.local
Traceback (most recent call last):
  File "/home/ubuntu/test-hrms/env/lib/python3.11/site-packages/redis/connection.py", line 699, in connect
    sock = self.retry.call_with_retry(
           ^^^^^^^^^^^^^^^^^^^^^^^^^^^
  File "/home/ubuntu/test-hrms/env/lib/python3.11/site-packages/redis/retry.py", line 46, in call_with_retry
    return do()
           ^^^^
  File "/home/ubuntu/test-hrms/env/lib/python3.11/site-packages/redis/connection.py", line 700, in <lambda>
    lambda: self._connect(), lambda error: self.disconnect(error)
            ^^^^^^^^^^^^^^^
  File "/home/ubuntu/test-hrms/env/lib/python3.11/site-packages/redis/connection.py", line 1002, in _connect
    raise err
  File "/home/ubuntu/test-hrms/env/lib/python3.11/site-packages/redis/connection.py", line 990, in _connect
    sock.connect(socket_address)
ConnectionRefusedError: [Errno 111] Connection refused

During handling of the above exception, another exception occurred:

Traceback (most recent call last):
  File "/home/ubuntu/test-hrms/apps/frappe/frappe/utils/scheduler.py", line 102, in enqueue_events_for_site
    enqueue_events(site=site)
  File "/home/ubuntu/test-hrms/apps/frappe/frappe/utils/scheduler.py", line 122, in enqueue_events
    if job_type.enqueue():
       ^^^^^^^^^^^^^^^^^^
  File "/home/ubuntu/test-hrms/apps/frappe/frappe/core/doctype/scheduled_job_type/scheduled_job_type.py", line 74, in enqueue
    if not self.is_job_in_queue():
           ^^^^^^^^^^^^^^^^^^^^^^
  File "/home/ubuntu/test-hrms/apps/frappe/frappe/core/doctype/scheduled_job_type/scheduled_job_type.py", line 95, in is_job_in_queue
    return is_job_enqueued(self.rq_job_id)
           ^^^^^^^^^^^^^^^^^^^^^^^^^^^^^^^
  File "/home/ubuntu/test-hrms/apps/frappe/frappe/utils/background_jobs.py", line 568, in is_job_enqueued
    return get_job_status(job_id) in (JobStatus.QUEUED, JobStatus.STARTED)
           ^^^^^^^^^^^^^^^^^^^^^^
  File "/home/ubuntu/test-hrms/apps/frappe/frappe/utils/background_jobs.py", line 573, in get_job_status
    job = get_job(job_id)
          ^^^^^^^^^^^^^^^
  File "/home/ubuntu/test-hrms/apps/frappe/frappe/utils/background_jobs.py", line 580, in get_job
    return Job.fetch(create_job_id(job_id), connection=get_redis_conn())
           ^^^^^^^^^^^^^^^^^^^^^^^^^^^^^^^^^^^^^^^^^^^^^^^^^^^^^^^^^^^^^
  File "/home/ubuntu/test-hrms/env/lib/python3.11/site-packages/rq/job.py", line 591, in fetch
    job.refresh()
  File "/home/ubuntu/test-hrms/env/lib/python3.11/site-packages/rq/job.py", line 989, in refresh
    data = self.connection.hgetall(self.key)
           ^^^^^^^^^^^^^^^^^^^^^^^^^^^^^^^^^
  File "/home/ubuntu/test-hrms/env/lib/python3.11/site-packages/redis/commands/core.py", line 4887, in hgetall
    return self.execute_command("HGETALL", name)
           ^^^^^^^^^^^^^^^^^^^^^^^^^^^^^^^^^^^^^
  File "/home/ubuntu/test-hrms/env/lib/python3.11/site-packages/redis/client.py", line 1266, in execute_command
    conn = self.connection or pool.get_connection(command_name, **options)
                              ^^^^^^^^^^^^^^^^^^^^^^^^^^^^^^^^^^^^^^^^^^^^
  File "/home/ubuntu/test-hrms/env/lib/python3.11/site-packages/redis/connection.py", line 1457, in get_connection
    connection.connect()
  File "/home/ubuntu/test-hrms/env/lib/python3.11/site-packages/redis/connection.py", line 705, in connect
    raise ConnectionError(self._error_message(e))
redis.exceptions.ConnectionError: Error 111 connecting to 127.0.0.1:11000. Connection refused.
2025-09-14 12:37:42,992 ERROR scheduler Exception in Enqueue Events for Site test-site.local
Traceback (most recent call last):
  File "/home/ubuntu/test-hrms/env/lib/python3.11/site-packages/redis/connection.py", line 699, in connect
    sock = self.retry.call_with_retry(
           ^^^^^^^^^^^^^^^^^^^^^^^^^^^
  File "/home/ubuntu/test-hrms/env/lib/python3.11/site-packages/redis/retry.py", line 46, in call_with_retry
    return do()
           ^^^^
  File "/home/ubuntu/test-hrms/env/lib/python3.11/site-packages/redis/connection.py", line 700, in <lambda>
    lambda: self._connect(), lambda error: self.disconnect(error)
            ^^^^^^^^^^^^^^^
  File "/home/ubuntu/test-hrms/env/lib/python3.11/site-packages/redis/connection.py", line 1002, in _connect
    raise err
  File "/home/ubuntu/test-hrms/env/lib/python3.11/site-packages/redis/connection.py", line 990, in _connect
    sock.connect(socket_address)
ConnectionRefusedError: [Errno 111] Connection refused

During handling of the above exception, another exception occurred:

Traceback (most recent call last):
  File "/home/ubuntu/test-hrms/apps/frappe/frappe/utils/scheduler.py", line 102, in enqueue_events_for_site
    enqueue_events(site=site)
  File "/home/ubuntu/test-hrms/apps/frappe/frappe/utils/scheduler.py", line 122, in enqueue_events
    if job_type.enqueue():
       ^^^^^^^^^^^^^^^^^^
  File "/home/ubuntu/test-hrms/apps/frappe/frappe/core/doctype/scheduled_job_type/scheduled_job_type.py", line 74, in enqueue
    if not self.is_job_in_queue():
           ^^^^^^^^^^^^^^^^^^^^^^
  File "/home/ubuntu/test-hrms/apps/frappe/frappe/core/doctype/scheduled_job_type/scheduled_job_type.py", line 95, in is_job_in_queue
    return is_job_enqueued(self.rq_job_id)
           ^^^^^^^^^^^^^^^^^^^^^^^^^^^^^^^
  File "/home/ubuntu/test-hrms/apps/frappe/frappe/utils/background_jobs.py", line 568, in is_job_enqueued
    return get_job_status(job_id) in (JobStatus.QUEUED, JobStatus.STARTED)
           ^^^^^^^^^^^^^^^^^^^^^^
  File "/home/ubuntu/test-hrms/apps/frappe/frappe/utils/background_jobs.py", line 573, in get_job_status
    job = get_job(job_id)
          ^^^^^^^^^^^^^^^
  File "/home/ubuntu/test-hrms/apps/frappe/frappe/utils/background_jobs.py", line 580, in get_job
    return Job.fetch(create_job_id(job_id), connection=get_redis_conn())
           ^^^^^^^^^^^^^^^^^^^^^^^^^^^^^^^^^^^^^^^^^^^^^^^^^^^^^^^^^^^^^
  File "/home/ubuntu/test-hrms/env/lib/python3.11/site-packages/rq/job.py", line 591, in fetch
    job.refresh()
  File "/home/ubuntu/test-hrms/env/lib/python3.11/site-packages/rq/job.py", line 989, in refresh
    data = self.connection.hgetall(self.key)
           ^^^^^^^^^^^^^^^^^^^^^^^^^^^^^^^^^
  File "/home/ubuntu/test-hrms/env/lib/python3.11/site-packages/redis/commands/core.py", line 4887, in hgetall
    return self.execute_command("HGETALL", name)
           ^^^^^^^^^^^^^^^^^^^^^^^^^^^^^^^^^^^^^
  File "/home/ubuntu/test-hrms/env/lib/python3.11/site-packages/redis/client.py", line 1266, in execute_command
    conn = self.connection or pool.get_connection(command_name, **options)
                              ^^^^^^^^^^^^^^^^^^^^^^^^^^^^^^^^^^^^^^^^^^^^
  File "/home/ubuntu/test-hrms/env/lib/python3.11/site-packages/redis/connection.py", line 1457, in get_connection
    connection.connect()
  File "/home/ubuntu/test-hrms/env/lib/python3.11/site-packages/redis/connection.py", line 705, in connect
    raise ConnectionError(self._error_message(e))
redis.exceptions.ConnectionError: Error 111 connecting to 127.0.0.1:11000. Connection refused.
2025-09-14 12:38:43,076 ERROR scheduler Exception in Enqueue Events for Site test-site.local
Traceback (most recent call last):
  File "/home/ubuntu/test-hrms/env/lib/python3.11/site-packages/redis/connection.py", line 699, in connect
    sock = self.retry.call_with_retry(
           ^^^^^^^^^^^^^^^^^^^^^^^^^^^
  File "/home/ubuntu/test-hrms/env/lib/python3.11/site-packages/redis/retry.py", line 46, in call_with_retry
    return do()
           ^^^^
  File "/home/ubuntu/test-hrms/env/lib/python3.11/site-packages/redis/connection.py", line 700, in <lambda>
    lambda: self._connect(), lambda error: self.disconnect(error)
            ^^^^^^^^^^^^^^^
  File "/home/ubuntu/test-hrms/env/lib/python3.11/site-packages/redis/connection.py", line 1002, in _connect
    raise err
  File "/home/ubuntu/test-hrms/env/lib/python3.11/site-packages/redis/connection.py", line 990, in _connect
    sock.connect(socket_address)
ConnectionRefusedError: [Errno 111] Connection refused

During handling of the above exception, another exception occurred:

Traceback (most recent call last):
  File "/home/ubuntu/test-hrms/apps/frappe/frappe/utils/scheduler.py", line 102, in enqueue_events_for_site
    enqueue_events(site=site)
  File "/home/ubuntu/test-hrms/apps/frappe/frappe/utils/scheduler.py", line 122, in enqueue_events
    if job_type.enqueue():
       ^^^^^^^^^^^^^^^^^^
  File "/home/ubuntu/test-hrms/apps/frappe/frappe/core/doctype/scheduled_job_type/scheduled_job_type.py", line 74, in enqueue
    if not self.is_job_in_queue():
           ^^^^^^^^^^^^^^^^^^^^^^
  File "/home/ubuntu/test-hrms/apps/frappe/frappe/core/doctype/scheduled_job_type/scheduled_job_type.py", line 95, in is_job_in_queue
    return is_job_enqueued(self.rq_job_id)
           ^^^^^^^^^^^^^^^^^^^^^^^^^^^^^^^
  File "/home/ubuntu/test-hrms/apps/frappe/frappe/utils/background_jobs.py", line 568, in is_job_enqueued
    return get_job_status(job_id) in (JobStatus.QUEUED, JobStatus.STARTED)
           ^^^^^^^^^^^^^^^^^^^^^^
  File "/home/ubuntu/test-hrms/apps/frappe/frappe/utils/background_jobs.py", line 573, in get_job_status
    job = get_job(job_id)
          ^^^^^^^^^^^^^^^
  File "/home/ubuntu/test-hrms/apps/frappe/frappe/utils/background_jobs.py", line 580, in get_job
    return Job.fetch(create_job_id(job_id), connection=get_redis_conn())
           ^^^^^^^^^^^^^^^^^^^^^^^^^^^^^^^^^^^^^^^^^^^^^^^^^^^^^^^^^^^^^
  File "/home/ubuntu/test-hrms/env/lib/python3.11/site-packages/rq/job.py", line 591, in fetch
    job.refresh()
  File "/home/ubuntu/test-hrms/env/lib/python3.11/site-packages/rq/job.py", line 989, in refresh
    data = self.connection.hgetall(self.key)
           ^^^^^^^^^^^^^^^^^^^^^^^^^^^^^^^^^
  File "/home/ubuntu/test-hrms/env/lib/python3.11/site-packages/redis/commands/core.py", line 4887, in hgetall
    return self.execute_command("HGETALL", name)
           ^^^^^^^^^^^^^^^^^^^^^^^^^^^^^^^^^^^^^
  File "/home/ubuntu/test-hrms/env/lib/python3.11/site-packages/redis/client.py", line 1266, in execute_command
    conn = self.connection or pool.get_connection(command_name, **options)
                              ^^^^^^^^^^^^^^^^^^^^^^^^^^^^^^^^^^^^^^^^^^^^
  File "/home/ubuntu/test-hrms/env/lib/python3.11/site-packages/redis/connection.py", line 1457, in get_connection
    connection.connect()
  File "/home/ubuntu/test-hrms/env/lib/python3.11/site-packages/redis/connection.py", line 705, in connect
    raise ConnectionError(self._error_message(e))
redis.exceptions.ConnectionError: Error 111 connecting to 127.0.0.1:11000. Connection refused.
2025-09-14 12:39:43,174 ERROR scheduler Exception in Enqueue Events for Site test-site.local
Traceback (most recent call last):
  File "/home/ubuntu/test-hrms/env/lib/python3.11/site-packages/redis/connection.py", line 699, in connect
    sock = self.retry.call_with_retry(
           ^^^^^^^^^^^^^^^^^^^^^^^^^^^
  File "/home/ubuntu/test-hrms/env/lib/python3.11/site-packages/redis/retry.py", line 46, in call_with_retry
    return do()
           ^^^^
  File "/home/ubuntu/test-hrms/env/lib/python3.11/site-packages/redis/connection.py", line 700, in <lambda>
    lambda: self._connect(), lambda error: self.disconnect(error)
            ^^^^^^^^^^^^^^^
  File "/home/ubuntu/test-hrms/env/lib/python3.11/site-packages/redis/connection.py", line 1002, in _connect
    raise err
  File "/home/ubuntu/test-hrms/env/lib/python3.11/site-packages/redis/connection.py", line 990, in _connect
    sock.connect(socket_address)
ConnectionRefusedError: [Errno 111] Connection refused

During handling of the above exception, another exception occurred:

Traceback (most recent call last):
  File "/home/ubuntu/test-hrms/apps/frappe/frappe/utils/scheduler.py", line 102, in enqueue_events_for_site
    enqueue_events(site=site)
  File "/home/ubuntu/test-hrms/apps/frappe/frappe/utils/scheduler.py", line 122, in enqueue_events
    if job_type.enqueue():
       ^^^^^^^^^^^^^^^^^^
  File "/home/ubuntu/test-hrms/apps/frappe/frappe/core/doctype/scheduled_job_type/scheduled_job_type.py", line 74, in enqueue
    if not self.is_job_in_queue():
           ^^^^^^^^^^^^^^^^^^^^^^
  File "/home/ubuntu/test-hrms/apps/frappe/frappe/core/doctype/scheduled_job_type/scheduled_job_type.py", line 95, in is_job_in_queue
    return is_job_enqueued(self.rq_job_id)
           ^^^^^^^^^^^^^^^^^^^^^^^^^^^^^^^
  File "/home/ubuntu/test-hrms/apps/frappe/frappe/utils/background_jobs.py", line 568, in is_job_enqueued
    return get_job_status(job_id) in (JobStatus.QUEUED, JobStatus.STARTED)
           ^^^^^^^^^^^^^^^^^^^^^^
  File "/home/ubuntu/test-hrms/apps/frappe/frappe/utils/background_jobs.py", line 573, in get_job_status
    job = get_job(job_id)
          ^^^^^^^^^^^^^^^
  File "/home/ubuntu/test-hrms/apps/frappe/frappe/utils/background_jobs.py", line 580, in get_job
    return Job.fetch(create_job_id(job_id), connection=get_redis_conn())
           ^^^^^^^^^^^^^^^^^^^^^^^^^^^^^^^^^^^^^^^^^^^^^^^^^^^^^^^^^^^^^
  File "/home/ubuntu/test-hrms/env/lib/python3.11/site-packages/rq/job.py", line 591, in fetch
    job.refresh()
  File "/home/ubuntu/test-hrms/env/lib/python3.11/site-packages/rq/job.py", line 989, in refresh
    data = self.connection.hgetall(self.key)
           ^^^^^^^^^^^^^^^^^^^^^^^^^^^^^^^^^
  File "/home/ubuntu/test-hrms/env/lib/python3.11/site-packages/redis/commands/core.py", line 4887, in hgetall
    return self.execute_command("HGETALL", name)
           ^^^^^^^^^^^^^^^^^^^^^^^^^^^^^^^^^^^^^
  File "/home/ubuntu/test-hrms/env/lib/python3.11/site-packages/redis/client.py", line 1266, in execute_command
    conn = self.connection or pool.get_connection(command_name, **options)
                              ^^^^^^^^^^^^^^^^^^^^^^^^^^^^^^^^^^^^^^^^^^^^
  File "/home/ubuntu/test-hrms/env/lib/python3.11/site-packages/redis/connection.py", line 1457, in get_connection
    connection.connect()
  File "/home/ubuntu/test-hrms/env/lib/python3.11/site-packages/redis/connection.py", line 705, in connect
    raise ConnectionError(self._error_message(e))
redis.exceptions.ConnectionError: Error 111 connecting to 127.0.0.1:11000. Connection refused.
